Workbook

Sheet 汇总
A1: 检索数据 | U1: 处理进度
B2: 整体检索量(除PDD) | E2: 整体违规量 | K2: 已知经销商 | Q2: 未知经销商 | U2: 整体 | X2: 已知经销商 | AA2: 未知经销商 淘宝
A3: 区域 | B3: 总检测链接(除PDD) | C3: 总违规链接(除PDD) | D3: 总违规链接%(除PDD) | E3: 总违规链接 | F3: 总违规链接% | G3: 总违规门店 | H3: 总违规门店% | I3: 总违规经销商 | J3: 总违规经销商% | K3: 违规链接数 | L3: 违规链接% | M3: 违规门店数 | N3: 违规门店% | O3: 违规经销商数 | P3: 违规经销商% | Q3: 违规链接数 | R3: 违规链接% | S3: 违规门店数 | T3: 违规门店% | U3: 总违规链接数 | V3: 调整/下架链接数量 | W3: 完成率 | X3: 违规链接 | Y3: 调整/下架链接数量 | Z3: 完成率 | AA3: 违规链接 | AB3: 调整/下架链接数量 | AC3: 完成率
A4: 广州大区 | B4: 439 | C4: 32 | D4: 0.072892938 | E4: 32 | F4: 0.091690544 | G4: 11 | H4: 0.085271318 | I4: 1 | J4: 0.071428571 | K4: 20 | L4: 0.1980198 | M4: 7 | N4: 0.25 | O4: 1 | P4: 0.071428571 | Q4: 12 | R4: 0.048387097 | S4: 4 | T4: 0.03960396 | U4: 32 | V4: 21 | W4: 0.65625 | X4: 20 | Y4: 20 | Z4: 1 | AA4: 12 | AB4: 1 | AC4: 0.083333333
A5: 深圳大区 | B5: 66 | C5: 6 | D5: 0.090909091 | E5: 6 | F5: 0.017191977 | G5: 5 | H5: 0.03875969 | I5: 0 | J5: 0 | K5: 0 | L5: 0 | M5: 0 | N5: 0 | O5: 0 | P5: 0 | Q5: 6 | R5: 0.024193548 | S5: 5 | T5: 0.04950495 | U5: 6 | V5: 2 | W5: 0.33333333 | X5: 0 | Y5: 0 | Z5: 0 | AA5: 6 | AB5: 2 | AC5: 0.33333333
A6: 华中大区 | B6: 209 | C6: 10 | D6: 0.04784689 | E6: 23 | F6: 0.065902579 | G6: 6 | H6: 0.046511628 | I6: 3 | J6: 0.21428571 | K6: 20 | L6: 0.1980198 | M6: 4 | N6: 0.14285714 | O6: 3 | P6: 0.21428571 | Q6: 3 | R6: 0.012096774 | S6: 2 | T6: 0.01980198 | U6: 23 | V6: 1 | W6: 0.043478261 | X6: 20 | Y6: 0 | Z6: 0 | AA6: 3 | AB6: 1 | AC6: 0.33333333
A7: 华东大区 | B7: 226 | C7: 37 | D7: 0.16371681 | E7: 37 | F7: 0.10601719 | G7: 11 | H7: 0.085271318 | I7: 1 | J7: 0.071428571 | K7: 11 | L7: 0.10891089 | M7: 2 | N7: 0.071428571 | O7: 1 | P7: 0.071428571 | Q7: 26 | R7: 0.10483871 | S7: 9 | T7: 0.089108911 | U7: 37 | V7: 5 | W7: 0.13513514 | X7: 11 | Y7: 0 | Z7: 0 | AA7: 26 | AB7: 5 | AC7: 0.19230769
A8: 上海大区 | B8: 236 | C8: 37 | D8: 0.15677966 | E8: 43 | F8: 0.12320917 | G8: 17 | H8: 0.13178295 | I8: 4 | J8: 0.28571429 | K8: 32 | L8: 0.31683168 | M8: 8 | N8: 0.28571429 | O8: 4 | P8: 0.28571429 | Q8: 11 | R8: 0.044354839 | S8: 9 | T8: 0.089108911 | U8: 43 | V8: 36 | W8: 0.8372093 | X8: 32 | Y8: 28 | Z8: 0.875 | AA8: 11 | AB8: 8 | AC8: 0.72727273
A9: 闽赣大区 | B9: 12 | C9: 1 | D9: 0.083333333 | E9: 1 | F9: 0.0028653295 | G9: 1 | H9: 0.007751938 | I9: 0 | J9: 0 | K9: 0 | L9: 0 | M9: 0 | N9: 0 | O9: 0 | P9: 0 | Q9: 1 | R9: 0.0040322581 | S9: 1 | T9: 0.0099009901 | U9: 1 | V9: 1 | W9: 1 | X9: 0 | Y9: 0 | Z9: 0 | AA9: 1 | AB9: 1 | AC9: 1
A10: 华北大区 | B10: 218 | C10: 16 | D10: 0.073394495 | E10: 17 | F10: 0.048710602 | G10: 11 | H10: 0.085271318 | I10: 2 | J10: 0.14285714 | K10: 6 | L10: 0.059405941 | M10: 3 | N10: 0.10714286 | O10: 2 | P10: 0.14285714 | Q10: 11 | R10: 0.044354839 | S10: 8 | T10: 0.079207921 | U10: 17 | V10: 3 | W10: 0.17647059 | X10: 6 | Y10: 0 | Z10: 0 | AA10: 11 | AB10: 3 | AC10: 0.27272727
A11: 西南大区 | B11: 55 | C11: 4 | D11: 0.072727273 | E11: 5 | F11: 0.014326648 | G11: 2 | H11: 0.015503876 | I11: 1 | J11: 0.071428571 | K11: 1 | L11: 0.0099009901 | M11: 1 | N11: 0.035714286 | O11: 1 | P11: 0.071428571 | Q11: 4 | R11: 0.016129032 | S11: 1 | T11: 0.0099009901 | U11: 5 | V11: 1 | W11: 0.2 | X11: 1 | Y11: 0 | Z11: 0 | AA11: 4 | AB11: 1 | AC11: 0.25
A12: 鲁豫陕大区 | B12: 162 | C12: 9 | D12: 0.055555556 | E12: 9 | F12: 0.025787966 | G12: 5 | H12: 0.03875969 | I12: 1 | J12: 0.071428571 | K12: 6 | L12: 0.059405941 | M12: 2 | N12: 0.071428571 | O12: 1 | P12: 0.071428571 | Q12: 3 | R12: 0.012096774 | S12: 3 | T12: 0.02970297 | U12: 9 | V12: 3 | W12: 0.33333333 | X12: 6 | Y12: 0 | Z12: 0 | AA12: 3 | AB12: 3 | AC12: 1
A13: 电商 | B13: 154 | C13: 5 | D13: 0.032467532 | E13: 5 | F13: 0.014326648 | G13: 1 | H13: 0.007751938 | I13: 1 | J13: 0.071428571 | K13: 5 | L13: 0.04950495 | M13: 1 | N13: 0.035714286 | O13: 1 | P13: 0.071428571 | Q13: 0 | R13: 0 | S13: 0 | T13: 0 | U13: 5 | V13: 0 | W13: 0 | X13: 5 | Y13: 0 | Z13: 0 | AA13: 0 | AB13: 0 | AC13: 0
A14: 无法判定大区 | B14: 1510 | C14: 56 | D14: 0.037086093 | E14: 171 | F14: 0.48997135 | G14: 59 | H14: 0.45736434 | I14: 0 | J14: 0 | K14: 0 | L14: 0 | M14: 0 | N14: 0 | O14: 0 | P14: 0 | Q14: 171 | R14: 0.68951613 | S14: 59 | T14: 0.58415842 | U14: 171 | V14: 51 | W14: 0.29824561 | X14: 0 | Y14: 0 | Z14: 0 | AA14: 171 | AB14: 51 | AC14: 0.29824561
A15: TTL | B15: 3287 | C15: 213 | D15: 0.06480073 | E15: 349 | F15: 1 | G15: 129 | H15: 1 | I15: 14 | J15: 1 | K15: 101 | L15: 1 | M15: 28 | N15: 1 | O15: 14 | P15: 1 | Q15: 248 | R15: 1 | S15: 101 | T15: 1 | U15: 349 | V15: 124 | W15: 0.35530086 | X15: 101 | Y15: 48 | Z15: 0.47524752 | AA15: 248 | AB15: 76 | AC15: 0.30645161
U18: 处理进度
A19: 仅餐后数据 | B19: 整体检索量(除PDD) | E19: 整体违规量 | K19: 已知经销商 | Q19: 未知经销商 | U19: 整体 | X19: 已知经销商 | AA19: 未知经销商 淘宝
A20: 区域 | B20: 总检测链接(除PDD) | C20: 总违规链接(除PDD) | D20: 总违规链接%(除PDD) | E20: 总违规链接 | F20: 总违规链接% | G20: 总违规门店 | H20: 总违规门店% | I20: 总违规经销商 | J20: 总违规经销商% | K20: 违规链接数 | L20: 违规链接% | M20: 违规门店数 | N20: 违规门店% | O20: 违规经销商数 | P20: 违规经销商% | Q20: 违规链接数 | R20: 违规链接% | S20: 违规门店数 | T20: 违规门店% | U20: 总违规链接数 | V20: 调整/下架链接数量 | W20: 完成率 | X20: 违规链接 | Y20: 调整/下架链接数量 | Z20: 完成率 | AA20: 违规链接 | AB20: 调整/下架链接数量 | AC20: 完成率
A21: 广州大区 | B21: 84 | C21: 4 | D21: 0.15384615 | E21: 4 | F21: 0.10810811 | G21: 3 | H21: 0.10344828 | I21: 1 | J21: 0.25 | K21: 2 | L21: 0.33333333 | M21: 2 | N21: 0.4 | O21: 1 | P21: 0.25 | Q21: 2 | R21: 0.064516129 | S21: 1 | T21: 0.041666667 | U21: 4 | V21: 2 | W21: 0.5 | X21: 2 | Y21: 2 | Z21: 1 | AA21: 2 | AB21: 0 | AC21: 0
A22: 深圳大区 | B22: 9 | C22: 1 | D22: 0.038461538 | E22: 1 | F22: 0.027027027 | G22: 1 | H22: 0.034482759 | I22: 0 | J22: 0 | K22: 0 | L22: 0 | M22: 0 | N22: 0 | O22: 0 | P22: 0 | Q22: 1 | R22: 0.032258065 | S22: 1 | T22: 0.041666667 | U22: 1 | V22: 0 | W22: 0 | X22: 0 | Y22: 0 | Z22: 0 | AA22: 1 | AB22: 0 | AC22: 0
A23: 华中大区 | B23: 23 | C23: 0 | D23: 0 | E23: 0 | F23: 0 | G23: 0 | H23: 0 | I23: 0 | J23: 0 | K23: 0 | L23: 0 | M23: 0 | N23: 0 | O23: 0 | P23: 0 | Q23: 0 | R23: 0 | S23: 0 | T23: 0 | U23: 0 | V23: 0 | W23: 0 | X23: 0 | Y23: 0 | Z23: 0 | AA23: 0 | AB23: 0 | AC23: 0
A24: 华东大区 | B24: 26 | C24: 0 | D24: 0 | E24: 0 | F24: 0 | G24: 0 | H24: 0 | I24: 0 | J24: 0 | K24: 0 | L24: 0 | M24: 0 | N24: 0 | O24: 0 | P24: 0 | Q24: 0 | R24: 0 | S24: 0 | T24: 0 | U24: 0 | V24: 0 | W24: 0 | X24: 0 | Y24: 0 | Z24: 0 | AA24: 0 | AB24: 0 | AC24: 0
A25: 上海大区 | B25: 50 | C25: 9 | D25: 0.34615385 | E25: 9 | F25: 0.24324324 | G25: 7 | H25: 0.24137931 | I25: 1 | J25: 0.25 | K25: 2 | L25: 0.33333333 | M25: 1 | N25: 0.2 | O25: 1 | P25: 0.25 | Q25: 7 | R25: 0.22580645 | S25: 6 | T25: 0.25 | U25: 9 | V25: 6 | W25: 0.66666667 | X25: 2 | Y25: 1 | Z25: 0.5 | AA25: 7 | AB25: 5 | AC25: 0.71428571
A26: 闽赣大区 | B26: 0 | C26: 0 | D26: 0 | E26: 0 | F26: 0 | G26: 0 | H26: 0 | I26: 0 | J26: 0 | K26: 0 | L26: 0 | M26: 0 | N26: 0 | O26: 0 | P26: 0 | Q26: 0 | R26: 0 | S26: 0 | T26: 0 | U26: 0 | V26: 0 | W26: 0 | X26: 0 | Y26: 0 | Z26: 0 | AA26: 0 | AB26: 0 | AC26: 0
A27: 华北大区 | B27: 38 | C27: 1 | D27: 0.038461538 | E27: 1 | F27: 0.027027027 | G27: 1 | H27: 0.034482759 | I27: 1 | J27: 0.25 | K27: 1 | L27: 0.16666667 | M27: 1 | N27: 0.2 | O27: 1 | P27: 0.25 | Q27: 0 | R27: 0 | S27: 0 | T27: 0 | U27: 1 | V27: 0 | W27: 0 | X27: 1 | Y27: 0 | Z27: 0 | AA27: 0 | AB27: 0 | AC27: 0
A28: 西南大区 | B28: 1 | C28: 0 | D28: 0 | E28: 0 | F28: 0 | G28: 0 | H28: 0 | I28: 0 | J28: 0 | K28: 0 | L28: 0 | M28: 0 | N28: 0 | O28: 0 | P28: 0 | Q28: 0 | R28: 0 | S28: 0 | T28: 0 | U28: 0 | V28: 0 | W28: 0 | X28: 0 | Y28: 0 | Z28: 0 | AA28: 0 | AB28: 0 | AC28: 0
A29: 鲁豫陕大区 | B29: 11 | C29: 1 | D29: 0.038461538 | E29: 1 | F29: 0.027027027 | G29: 1 | H29: 0.034482759 | I29: 1 | J29: 0.25 | K29: 1 | L29: 0.16666667 | M29: 1 | N29: 0.2 | O29: 1 | P29: 0.25 | Q29: 0 | R29: 0 | S29: 0 | T29: 0 | U29: 1 | V29: 0 | W29: 0 | X29: 1 | Y29: 0 | Z29: 0 | AA29: 0 | AB29: 0 | AC29: 0
A30: 电商 | B30: 15 | C30: 0 | D30: 0 | E30: 0 | F30: 0 | G30: 0 | H30: 0 | I30: 0 | J30: 0 | K30: 0 | L30: 0 | M30: 0 | N30: 0 | O30: 0 | P30: 0 | Q30: 0 | R30: 0 | S30: 0 | T30: 0 | U30: 0 | V30: 0 | W30: 0 | X30: 0 | Y30: 0 | Z30: 0 | AA30: 0 | AB30: 0 | AC30: 0
A31: 无法判定大区 | B31: 328 | C31: 10 | D31: 0.38461538 | E31: 21 | F31: 0.56756757 | G31: 16 | H31: 0.55172414 | I31: 0 | J31: 0 | K31: 0 | L31: 0 | M31: 0 | N31: 0 | O31: 0 | P31: 0 | Q31: 21 | R31: 0.67741935 | S31: 16 | T31: 0.66666667 | U31: 21 | V31: 15 | W31: 0.71428571 | X31: 0 | Y31: 0 | Z31: 0 | AA31: 21 | AB31: 15 | AC31: 0.71428571
A32: TTL | B32: 585 | C32: 26 | D32: 1 | E32: 37 | F32: 1 | G32: 29 | H32: 1 | I32: 4 | J32: 1 | K32: 6 | L32: 1 | M32: 5 | N32: 1 | O32: 4 | P32: 1 | Q32: 31 | R32: 1 | S32: 24 | T32: 1 | U32: 37 | V32: 23 | W32: 0.62162162 | X32: 6 | Y32: 3 | Z32: 0.5 | AA32: 31 | AB32: 20 | AC32: 0.64516129 | AE32: 0.83783784

Sheet 总数据
A1: 年月 | B1: 核检日期 | C1: 所属大区 | D1: 更新经销商 | E1: 平台名称 | F1: 发货地区 | G1: 店铺名称 | H1: 商品链接 | I1: 型号 | J1: 数量 | K1: 平台促销价 | L1: 2026年1月促销价格指引 | M1: 售卖单价 （PC） | N1: 促销价是否比红线价低 | O1: 处理大区 | P1: 负责人 | Q1: 整改时间 | R1: 反馈整改图片 | S1: 谁处理问题 | T1: 处理时间 | U1: 处理结果 | V1: 优惠信息 | W1: 商品ID | X1: spu名称 | Y1: sku描述 | Z1: skuid | AA1: 换算价 | AB1: 差价 | AC1: 正常价 | AD1: 销量
A2: 46082 | B2: 46084 | C2: 无法判定大区 | D2: 未知经销商 | E2: 京东 | G2: 拓旭冲饮谷物专营店 | H2: https://item.jd.com/10140930409661.html | I2: 卡士餐后一小时无蔗糖原味250g | J2: 3 | K2: 40 | L2: =VLOOKUP(I:I,[1]指导价!$A:$B,2,0) -> 10.9 | M2: =K2/J2 -> 13.333333 | N2: 否 | W2: 10140930409661 | X2: 食怀【顺丰】卡士酸奶餐后一小时250g*12瓶原味双歧杆菌48小时发货 【0蔗糖组合】 | Y2: 食怀【顺丰】卡士酸奶餐后一小时250g*12瓶原味双歧杆菌48小时发货 【0蔗糖组合】 | Z2: 10140930409661 | AA2: =J2*L2 -> 32.7 | AB2: =K:K-AA:AA -> 7.3
A3: 46082 | B3: 46084 | C3: 无法判定大区 | D3: 未知经销商 | E3: 京东 | G3: 风韵点心专营店 | H3: https://item.jd.com/10166064336105.html | I3: 卡士餐后一小时原味250g | J3: 3 | K3: 42 | L3: =VLOOKUP(I:I,[1]指导价!$A:$B,2,0) -> 10.9 | M3: =K3/J3 -> 14 | N3: 否 | W3: 10166064336105 | X3: 碧淼芬晨【顺丰】卡士酸奶餐后一小时250g*12瓶原味双歧杆菌48小时发货 [0蔗糖组合] | Y3: 碧淼芬晨【顺丰】卡士酸奶餐后一小时250g*12瓶原味双歧杆菌48小时发货 [0蔗糖组合] | Z3: 10166064336105 | AA3: =J3*L3 -> 32.7 | AB3: =K:K-AA:AA -> 9.3
A4: 46082 | B4: 46084 | C4: 上海大区 | D4: 未知经销商 | E4: 淘宝/天猫 | F4: 上海 | G4: 屹天食品专营店 | H4: https://detail.tmall.com/item.htm?id=687622040734 | I4: 卡士007益生菌家庭装酸奶原味1kg（含港澳版） | J4: 1 | K4: 29.9 | L4: =VLOOKUP(I:I,[1]指导价!$A:$B,2,0) -> 24.9 | M4: =K4/J4 -> 29.9 | N4: 否 | V4: 淘金币频道抵扣11%起 | W4: 687622040734 | X4: 卡士007家庭装酸奶原味1kg瓶装0食品添加7种益生菌低温风味发酵乳 | Y4: 【红色007原味】家庭装1Kg,1瓶 | Z4: 4901168272429 | AA4: =J4*L4 -> 24.9 | AB4: =K:K-AA:AA -> 5
A5: 46082 | B5: 46084 | C5: =VLOOKUP(G5,白名单!C:E,3,0) -> 上海大区 | D5: 上海晗臻实业有限公司 | E5: 淘宝/天猫 | F5: 上海 | G5: 晗臻尤品 | H5: https://item.taobao.com/item.htm?id=856684567883 | I5: 卡士宝贝第二餐儿童酸奶（原味、西梅苹果味无蔗糖、4%蔗糖草莓蓝莓树莓味、4%蔗糖山楂六物味）（单袋85g） 单袋 | J5: 4 | K5: 26.4 | L5: =VLOOKUP(I:I,[1]指导价!$A:$B,2,0) -> 6.6 | M5: =K5/J5 -> 6.6 | N5: 否 | V5: 淘金币频道抵扣5%起 | W5: 856684567883 | X5: 卡士酸奶宝贝第二餐系列原味山楂草莓蓝莓西梅85g/袋儿童酸奶 | Y5: 宝贝第二餐 原味85g*4袋 | Z5: 5831619034398 | AA5: =J5*L5 -> 26.4 | AB5: =K:K-AA:AA -> 0
A6: 46082 | B6: 46084 | C6: =VLOOKUP(G6,白名单!C:E,3,0) -> 上海大区 | D6: 上海晗臻实业有限公司 | E6: 淘宝/天猫 | F6: 上海 | G6: 晗臻尤品 | H6: https://item.taobao.com/item.htm?id=926290113870 | I6: 卡士007小瓶装益生菌酸奶原味 220g | J6: 3 | K6: 26.7 | L6: =VLOOKUP(I:I,[1]指导价!$A:$B,2,0) -> 8.9 | M6: =K6/J6 -> 8.9 | N6: 否 | V6: 淘金币频道抵扣5%起 | W6: 926290113870 | X6: 卡士007AD钙原味牛油果草莓味酸奶风味发酵乳0添加儿童早餐210g | Y6: 卡士AD钙酸奶220g*3瓶 | Z6: 5805744960614 | AA6: =J6*L6 -> 26.7 | AB6: =K:K-AA:AA -> 0
A7: 46082 | B7: 46084 | C7: =VLOOKUP(G7,白名单!C:E,3,0) -> 上海大区 | D7: 上海晗臻实业有限公司 | E7: 淘宝/天猫 | F7: 上海 | G7: 晗臻尤品 | H7: https://item.taobao.com/item.htm?id=793884212333 | I7: 卡士007无蔗糖益生菌家庭装酸奶原味969g 单瓶 | J7: 1 | K7: 24.9 | L7: =VLOOKUP(I:I,[1]指导价!$A:$B,2,0) -> 24.9 | M7: =K7/J7 -> 24.9 | N7: 否 | V7: 淘金币频道抵扣5%起 | W7: 793884212333 | X7: 清仓特价卡士007家庭装原味969g0食品添加乳酸菌低温酸奶 | Y7: 卡士酸奶969g*1瓶 | Z7: 5418212128171 | AA7: =J7*L7 -> 24.9 | AB7: =K:K-AA:AA -> 0
A8: 46082 | B8: 46084 | C8: =VLOOKUP(G8,白名单!C:E,3,0) -> 上海大区 | D8: 上海晗臻实业有限公司 | E8: 淘宝/天猫 | F8: 上海 | G8: 晗臻尤品 | H8: https://item.taobao.com/item.htm?id=856030627488 | I8: 卡士007益生菌酸奶原味440g 单瓶 | J8: 4 | K8: 39.6 | L8: =VLOOKUP(I:I,[1]指导价!$A:$B,2,0) -> 9.9 | M8: =K8/J8 -> 9.9 | N8: 否 | V8: 淘金币频道抵扣5%起 | W8: 856030627488 | X8: 卡士酸奶007小奶罐风味发酵乳7种益生菌0添加营养早餐奶440g/428g | Y8: （红）007小奶罐440g,4瓶 | Z8: 5831038787751 | AA8: =J8*L8 -> 39.6 | AB8: =K:K-AA:AA -> 0
A9: 46082 | B9: 46084 | C9: 华东大区 | D9: 未知经销商 | E9: 淘宝/天猫 | F9: 江苏徐州 | G9: 1展建生活一 | H9: https://item.taobao.com/item.htm?id=1006198786644 | I9: 卡士宝贝第二餐儿童酸奶（原味、西梅苹果味无蔗糖、4%蔗糖草莓蓝莓树莓味、4%蔗糖山楂六物味）（单袋85g） 单袋 | J9: 12 | K9: 117.36 | L9: =VLOOKUP(I:I,[1]指导价!$A:$B,2,0) -> 6.6 | M9: =K9/J9 -> 9.78 | N9: 否 | W9: 1006198786644 | X9: 【孩子喝选我】卡士宝贝第二餐儿童新鲜优质酸奶吸收营养低温酸奶 | Y9: 口味:原味12袋（0蔗糖） | Z9: 6002648984900 | AA9: =J9*L9 -> 79.2 | AB9: =K:K-AA:AA -> 38.16
A10: 46082 | B10: 46084 | C10: 华东大区 | D10: 未知经销商 | E10: 淘宝/天猫 | F10: 江苏徐州 | G10: 1展建生活一 | H10: https://item.taobao.com/item.htm?id=1006763173764 | I10: 卡士宝贝第二餐儿童酸奶（原味、西梅苹果味无蔗糖、4%蔗糖草莓蓝莓树莓味、4%蔗糖山楂六物味）（单袋85g） 单袋 | J10: 12 | K10: 117.72 | L10: =VLOOKUP(I:I,[1]指导价!$A:$B,2,0) -> 6.6 | M10: =K10/J10 -> 9.81 | N10: 否 | W10: 1006763173764 | X10: 【孩子喝选我】卡士宝贝第二餐儿童新鲜优质酸奶吸收营养低温酸奶 | Y10: 口味:原味12袋（0蔗糖） | Z10: 6003756317154 | AA10: =J10*L10 -> 79.2 | AB10: =K:K-AA:AA -> 38.52
A11: 46082 | B11: 46084 | C11: 华东大区 | D11: 未知经销商 | E11: 淘宝/天猫 | F11: 浙江杭州 | G11: 3彤羽精品特价店 | H11: https://item.taobao.com/item.htm?id=1006354257471 | I11: 卡士007益生菌酸奶原味440g 单瓶 | J11: 5 | K11: 103.61 | L11: =VLOOKUP(I:I,[1]指导价!$A:$B,2,0) -> 9.9 | M11: =K11/J11 -> 20.722 | N11: 否 | W11: 1006354257471 | X11: 卡士酸奶007益生菌风味发酵乳零0蔗糖428g早餐奶原味440g小奶罐 | Y11: 颜色分类:007益生菌原味440g*5瓶 | Z11: 6166600699557 | AA11: =J11*L11 -> 49.5 | AB11: =K:K-AA:AA -> 54.11
A12: 46082 | B12: 46084 | C12: 华东大区 | D12: 未知经销商 | E12: 淘宝/天猫 | F12: 浙江杭州 | G12: 4哚雨精品特价店 | H12: https://item.taobao.com/item.htm?id=938569692128 | I12: 卡士007无蔗糖益生菌酸奶原味428g 单瓶 | J12: 6 | K12: 83.83 | L12: =VLOOKUP(I:I,[1]指导价!$A:$B,2,0) -> 9.9 | M12: =K12/J12 -> 13.971667 | N12: 否 | W12: 938569692128 | X12: 卡士酸奶007小奶罐风味发酵乳7种益生菌0添加营养早餐奶440g/428g | Y12: 奶粉种类:6瓶、（蓝）007小奶罐428g | Z12: 5999058111050 | AA12: =J12*L12 -> 59.4 | AB12: =K:K-AA:AA -> 24.43
A13: 46082 | B13: 46084 | C13: 广州大区 | D13: 未知经销商 | E13: 淘宝/天猫 | F13: 广东东莞 | G13: classykiss卡士宫荼专卖店 | H13: https://detail.tmall.com/item.htm?id=891689798607 | I13: 卡士宝贝第二餐儿童酸奶（原味、西梅苹果味无蔗糖、4%蔗糖草莓蓝莓树莓味、4%蔗糖山楂六物味）（单袋85g） 单袋 | J13: 12 | K13: 82.04 | L13: =VLOOKUP(I:I,[1]指导价!$A:$B,2,0) -> 6.6 | M13: =K13/J13 -> 6.8366667 | N13: 否 | W13: 891689798607 | X13: 卡士宝贝第二餐儿童低温酸奶0%/4%蔗糖可选控糖宝宝85g*12袋 | Y13: 口味:12袋】卡士第二餐原味0糖 | Z13: 5905484770700 | AA13: =J13*L13 -> 79.2 | AB13: =K:K-AA:AA -> 2.84
A14: 46082 | B14: 46084 | C14: 广州大区 | D14: 未知经销商 | E14: 淘宝/天猫 | F14: 广东东莞 | G14: classykiss卡士宫荼专卖店 | H14: https://detail.tmall.com/item.htm?id=892493620491 | I14: 卡士007益生菌酸奶原味440g 单瓶 | J14: 5 | K14: 67.28 | L14: =VLOOKUP(I:I,[1]指导价!$A:$B,2,0) -> 9.9 | M14: =K14/J14 -> 13.456 | N14: 否 | W14: 892493620491 | X14: 卡士酸奶007小奶罐益生菌原味酸奶/0蔗糖酸奶整箱早餐奶营养 | Y14: 口味:5瓶】小奶罐有甜味440g/瓶 | Z14: 5906944027251 | AA14: =J14*L14 -> 49.5 | AB14: =K:K-AA:AA -> 17.78
A15: 46082 | B15: 46084 | C15: 广州大区 | D15: 未知经销商 | E15: 淘宝/天猫 | F15: 广东东莞 | G15: classykiss卡士宫荼专卖店 | H15: https://detail.tmall.com/item.htm?id=891445747790 | I15: 卡士007益生菌家庭装酸奶原味1kg（含港澳版） | J15: 2 | K15: 50.99 | L15: =VLOOKUP(I:I,[1]指导价!$A:$B,2,0) -> 24.9 | M15: =K15/J15 -> 25.495 | N15: 否 | W15: 891445747790 | X15: 卡士酸奶007家庭装低温益生菌原味营养早餐大瓶酸奶 | Y15: 口味:2瓶】卡士有甜味1kg/瓶 | Z15: 5738107708091 | AA15: =J15*L15 -> 49.8 | AB15: =K:K-AA:AA -> 1.19
A16: 46082 | B16: 46084 | C16: 广州大区 | D16: 未知经销商 | E16: 淘宝/天猫 | F16: 广东东莞 | G16: classykiss卡士宫荼专卖店 | H16: https://detail.tmall.com/item.htm?id=928822415674 | I16: 卡士007益生菌酸奶原味440g 单瓶 | J16: 4 | K16: 54.87 | L16: =VLOOKUP(I:I,[1]指导价!$A:$B,2,0) -> 9.9 | M16: =K16/J16 -> 13.7175 | N16: 否 | W16: 928822415674 | X16: 卡士酸奶007小奶罐0添加剂风味发酵乳低温益生菌酸奶 | Y16: 口味:4瓶】小奶罐原味440g/瓶 | Z16: 5812775868743 | AA16: =J16*L16 -> 39.6 | AB16: =K:K-AA:AA -> 15.27
A17: 46082 | B17: 46084 | C17: =VLOOKUP(G17,白名单!C:E,3,0) -> 电商 | D17: =VLOOKUP(G17,白名单!C:F,4,0) -> 电商 | E17: 淘宝/天猫 | F17: 广东深圳 | G17: classykiss卡士旗舰店 | H17: https://item.taobao.com/item.htm?id=636881400574 | I17: 卡士007益生菌家庭装酸奶原味1kg（含港澳版） | J17: 2 | K17: 59.1 | L17: =VLOOKUP(I:I,[1]指导价!$A:$B,2,0) -> 24.9 | M17: =K17/J17 -> 29.55 | N17: 否 | V17: 满79.0减10.0；补贴9.9元；淘金币频道抵扣3%起；商品券 | 满79减10；商品券 | 满118减29 | W17: 636881400574 | X17: 卡士低温酸奶007益生菌家庭装原味低温酸奶营养早餐酸奶1kg/969g | Y17: 原味（红瓶1kg）,2瓶 | Z17: 5493213765168 | AA17: =J17*L17 -> 49.8 | AB17: =K:K-AA:AA -> 9.3
A18: 46082 | B18: 46084 | C18: =VLOOKUP(G18,白名单!C:E,3,0) -> 电商 | D18: =VLOOKUP(G18,白名单!C:F,4,0) -> 电商 | E18: 淘宝/天猫 | F18: 广东深圳 | G18: classykiss卡士旗舰店 | H18: https://detail.tmall.com/item.htm?id=662282297632 | I18: 卡士007无蔗糖益生菌家庭装酸奶原味969g 单瓶 | J18: 2 | K18: 59.1 | L18: =VLOOKUP(I:I,[1]指导价!$A:$B,2,0) -> 24.9 | M18: =K18/J18 -> 29.55 | N18: 否 | V18: 满79.0减10.0；补贴9.9元；淘金币频道抵扣3%起；商品券 | 满79减10；商品券 | 满118减29 | W18: 662282297632 | X18: 卡士007家庭装无蔗糖酸奶969g经典原味1000g早餐低温酸奶益生菌 | Y18: 【蓝瓶】007无蔗糖酸奶969g,2瓶 | Z18: 6037974939197 | AA18: =J18*L18 -> 49.8 | AB18: =K:K-AA:AA -> 9.3
A19: 46082 | B19: 46084 | C19: =VLOOKUP(G19,白名单!C:E,3,0) -> 电商 | D19: =VLOOKUP(G19,白名单!C:F,4,0) -> 电商 | E19: 淘宝/天猫 | F19: 广东深圳 | G19: classykiss卡士旗舰店 | H19: https://detail.tmall.com/item.htm?id=907933179827 | I19: 卡士007AD钙益生菌酸奶-果味-210g | J19: 1 | K19: 20 | L19: =VLOOKUP(I:I,[1]指导价!$A:$B,2,0) -> 8.9 | M19: =K19/J19 -> 20 | N19: 否 | V19: 满120.0减70.0；买6件49.92元；淘金币频道抵扣3%起；2件减0.1元；满50减10，部分用户可领；商品券 | 满120减70 | W19: 907933179827 | X19: 卡士旗舰店•AD钙酸奶合集220g/210g | Y19: 【原味】220g*1瓶 | Z19: 6134796815142 | AA19: =J19*L19 -> 8.9 | AB19: =K:K-AA:AA -> 11.1
A20: 46082 | B20: 46084 | C20: =VLOOKUP(G20,白名单!C:E,3,0) -> 电商 | D20: =VLOOKUP(G20,白名单!C:F,4,0) -> 电商 | E20: 淘宝/天猫 | F20: 广东深圳 | G20: classykiss卡士旗舰店 | H20: https://detail.tmall.com/item.htm?id=996844235656 | I20: 卡士007益生菌酸奶原味440g 单瓶 | J20: 1 | K20: 30 | L20: =VLOOKUP(I:I,[1]指导价!$A:$B,2,0) -> 9.9 | M20: =K20/J20 -> 30 | N20: 否 | V20: 满180.0减120.0；买6件59.88元；2件减0.1元；淘金币频道抵扣2%起；满50减10，部分用户可领；商品券 | 满180减120 | W20: 996844235656 | X20: 卡士益生菌小奶罐低温酸奶440g | Y20: 【原味1瓶】红瓶小奶罐440g | Z20: 6146573515948 | AA20: =J20*L20 -> 9.9 | AB20: =K:K-AA:AA -> 20.1
A21: 46082 | B21: 46084 | C21: =VLOOKUP(G21,白名单!C:E,3,0) -> 电商 | D21: =VLOOKUP(G21,白名单!C:F,4,0) -> 电商 | E21: 淘宝/天猫 | F21: 广东深圳 | G21: classykiss卡士旗舰店 | H21: https://detail.tmall.com/item.htm?id=953767812999 | I21: 卡士吃酸大果粒风味发酵乳系列(黄桃、酸木瓜、粉芭乐）3联 | J21: 1 | K21: 99 | L21: =VLOOKUP(I:I,[1]指导价!$A:$B,2,0) -> 32.9 | M21: =K21/J21 -> 99 | N21: 否 | V21: 2件减0.1元；淘金币频道抵扣1%起 | W21: 953767812999 | X21: 【专享】卡士吃酸系列风味发酵乳大颗果肉低温酸奶140g*3杯 | Y21: 【3杯】酸木瓜双柚芦荟风味140g | Z21: 5871697960252 | AA21: =J21*L21 -> 32.9 | AB21: =K:K-AA:AA -> 66.1
A22: 46082 | B22: 46084 | C22: =VLOOKUP(G22,白名单!C:E,3,0) -> 电商 | D22: =VLOOKUP(G22,白名单!C:F,4,0) -> 电商 | E22: 淘宝/天猫 | F22: 广东深圳 | G22: classykiss卡士旗舰店 | H22: https://detail.tmall.com/item.htm?id=766939146875 | I22: 卡士007益生菌酸奶原味440g 单瓶 | J22: 6 | K22: 75.8 | L22: =VLOOKUP(I:I,[1]指导价!$A:$B,2,0) -> 9.9 | M22: =K22/J22 -> 12.633333 | N22: 否 | V22: 直降24元；淘金币频道抵扣3%起 | W22: 766939146875 | X22: 卡士低温酸奶007益生菌小奶罐6瓶风味发酵乳7种益生菌营养早餐奶 | Y22: 【经典原味】红瓶440g,6瓶 | Z22: 6151351726631 | AA22: =J22*L22 -> 59.4 | AB22: =K:K-AA:AA -> 16.4
A23: 46082 | B23: 46084 | C23: =VLOOKUP(G23,白名单!C:E,3,0) -> 电商 | D23: =VLOOKUP(G23,白名单!C:F,4,0) -> 电商 | E23: 淘宝/天猫 | F23: 广东深圳 | G23: classykiss卡士旗舰店 | H23: https://item.taobao.com/item.htm?id=937352766205 | I23: 卡士吃酸大果粒风味发酵乳系列(黄桃、酸木瓜、粉芭乐）3联 | J23: 2 | K23: 65.8 | L23: =VLOOKUP(I:I,[1]指导价!$A:$B,2,0) -> 32.9 | M23: =K23/J23 -> 32.9 | N23: 否 | V23: 满49.0减11.0；补贴6元；满50减10，部分用户可领；商品券 | 满49减11；商品券 | 满91减14 | W23: 937352766205 | X23: 【新品】卡士吃酸系列大颗果肉风味发酵乳酸木瓜芭乐低温酸奶140g | Y23: 【热卖3+3】酸木瓜味140g*3+粉芭乐味140g*3 | Z23: 5889572797305 | AA23: =J23*L23 -> 65.8 | AB23: =K:K-AA:AA -> 0
A24: 46082 | B24: 46084 | C24: =VLOOKUP(G24,白名单!C:E,3,0) -> 电商 | D24: =VLOOKUP(G24,白名单!C:F,4,0) -> 电商 | E24: 淘宝/天猫 | F24: 广东深圳 | G24: classykiss卡士旗舰店 | H24: https://detail.tmall.com/item.htm?id=721208376511 | I24: 卡士宝贝第二餐儿童酸奶（原味、西梅苹果味无蔗糖、4%蔗糖草莓蓝莓树莓味、4%蔗糖山楂六物味）（单袋85g） 单袋 | J24: 9 | K24: 79.3 | L24: =VLOOKUP(I:I,[1]指导价!$A:$B,2,0) -> 6.6 | M24: =K24/J24 -> 8.8111111 | N24: 否 | V24: 满98.0减7.0；补贴11.9元；淘金币频道抵扣3%起；满50减10，部分用户可领；商品券 | 满98减7；商品券 | 满132减11 | W24: 721208376511 | X24: 卡士低温酸奶宝贝第二餐儿童低温酸奶4%蔗糖草莓蓝莓树莓味 | Y24: 【0%蔗糖】原味,9袋 | Z24: 5297289502408 | AA24: =J24*L24 -> 59.4 | AB24: =K:K-AA:AA -> 19.9
A25: 46082 | B25: 46084 | C25: =VLOOKUP(G25,白名单!C:E,3,0) -> 电商 | D25: =VLOOKUP(G25,白名单!C:F,4,0) -> 电商 | E25: 淘宝/天猫 | F25: 广东深圳 | G25: classykiss卡士旗舰店 | H25: https://detail.tmall.com/item.htm?id=733236245113 | I25: 卡士宝贝第二餐儿童酸奶（原味、西梅苹果味无蔗糖、4%蔗糖草莓蓝莓树莓味、4%蔗糖山楂六物味）（单袋85g） 单袋 | J25: 3 | K25: 99 | L25: =VLOOKUP(I:I,[1]指导价!$A:$B,2,0) -> 6.6 | M25: =K25/J25 -> 33 | N25: 否 | V25: 满297.0减237.0；买3件59.91元；2件减0.1元；淘金币频道抵扣1%起；满50减10，部分用户可领；商品券 | 满297减237 | W25: 733236245113 | X25: 卡士宝贝第二餐0/4%蔗糖低温儿童酸奶 | Y25: 【3袋丨0%蔗糖】原味 | Z25: 5247473183351 | AA25: =J25*L25 -> 19.8 | AB25: =K:K-AA:AA -> 79.2
A26: 46082 | B26: 46084 | C26: =VLOOKUP(G26,白名单!C:E,3,0) -> 广州大区 | D26: =VLOOKUP(G26,白名单!C:F,4,0) -> 广州喜万佳便利店有限公司 | E26: 淘宝/天猫 | F26: 广东广州 | G26: CLASSYKISS乳品企业店 | H26: https://item.taobao.com/item.htm?id=671032744886 | I26: 卡士007无蔗糖益生菌家庭装酸奶原味969g 单瓶 | J26: 1 | K26: 36.24 | L26: =VLOOKUP(I:I,[1]指导价!$A:$B,2,0) -> 24.9 | M26: =K26/J26 -> 36.24 | N26: 否 | W26: 671032744886 | X26: 卡士007益生菌酸奶969g大瓶原味0蔗糖健身孕妇宝宝老人控糖代餐奶 | Y26: 口味:【1瓶】家庭装原味969g | Z26: 5803626059608 | AA26: =J26*L26 -> 24.9 | AB26: =K:K-AA:AA -> 11.34
A27: 46082 | B27: 46084 | C27: 华东大区 | D27: 未知经销商 | E27: 淘宝/天猫 | F27: 江苏苏州 | G27: CLASSYKISS乳品线上店 | H27: https://item.taobao.com/item.htm?id=935092711201 | I27: 卡士007无蔗糖益生菌家庭装酸奶原味969g 单瓶 | J27: 1 | K27: 37.56 | L27: =VLOOKUP(I:I,[1]指导价!$A:$B,2,0) -> 24.9 | M27: =K27/J27 -> 37.56 | N27: 否 | W27: 935092711201 | X27: 顺丰包邮卡士酸奶007大瓶装969g0零蔗糖生牛乳益生菌营养早餐奶 | Y27: 罐数:1瓶;口味:007家庭装零蔗糖969g | Z27: 5993417838469 | AA27: =J27*L27 -> 24.9 | AB27: =K:K-AA:AA -> 12.66
A28: 46082 | B28: 46084 | C28: 华东大区 | D28: 未知经销商 | E28: 淘宝/天猫 | F28: 江苏苏州 | G28: CLASSYKISS乳品线上店 | H28: https://item.taobao.com/item.htm?id=938723296327 | I28: 卡士007无蔗糖益生菌酸奶原味428g 单瓶 | J28: 3 | K28: 47.95 | L28: =VLOOKUP(I:I,[1]指导价!$A:$B,2,0) -> 9.9 | M28: =K28/J28 -> 15.983333 | N28: 否 | W28: 938723296327 | X28: 顺丰包邮卡士007酸奶家庭装零蔗糖益生菌大瓶428g/969g早餐奶学生 | Y28: 口味:007益生菌428g零蔗糖*3瓶 | Z28: 5833124341219 | AA28: =J28*L28 -> 29.7 | AB28: =K:K-AA:AA -> 18.25
A29: 46082 | B29: 46084 | C29: 华东大区 | D29: 未知经销商 | E29: 淘宝/天猫 | F29: 江苏苏州 | G29: CLASSYKISS乳品线上店 | H29: https://item.taobao.com/item.htm?id=937084466981 | I29: 卡士007益生菌酸奶原味440g 单瓶 | J29: 3 | K29: 47.55 | L29: =VLOOKUP(I:I,[1]指导价!$A:$B,2,0) -> 9.9 | M29: =K29/J29 -> 15.85 | N29: 否 | W29: 937084466981 | X29: 顺丰包邮卡士酸奶007风味发酵乳零0蔗糖原味440g早餐奶益生菌428g | Y29: 口味:007益生菌原味440g*3瓶 | Z29: 5830205640942 | AA29: =J29*L29 -> 29.7 | AB29: =K:K-AA:AA -> 17.85
A30: 46082 | B30: 46084 | C30: 华东大区 | D30: 未知经销商 | E30: 淘宝/天猫 | F30: 江苏苏州 | G30: CLASSYKISS乳品线上店 | H30: https://item.taobao.com/item.htm?id=1007375036458 | I30: 卡士007益生菌家庭装酸奶原味1kg（含港澳版） | J30: 2 | K30: 60.51 | L30: =VLOOKUP(I:I,[1]指导价!$A:$B,2,0) -> 24.9 | M30: =K30/J30 -> 30.255 | N30: 否 | W30: 1007375036458 | X30: 顺丰包邮卡士酸奶007益生菌原味风味发酵乳早餐1kg营养儿童奶大瓶 | Y30: 口味:007益生菌家庭装原味1kg*2瓶 | Z30: 6167321723784 | AA30: =J30*L30 -> 49.8 | AB30: =K:K-AA:AA -> 10.71
A31: 46082 | B31: 46084 | C31: 华东大区 | D31: 未知经销商 | E31: 淘宝/天猫 | F31: 江苏苏州 | G31: CLASSYKISS乳品线上店 | H31: https://item.taobao.com/item.htm?id=936580188427 | I31: 卡士007益生菌家庭装酸奶原味1kg（含港澳版） | J31: 1 | K31: 37.53 | L31: =VLOOKUP(I:I,[1]指导价!$A:$B,2,0) -> 24.9 | M31: =K31/J31 -> 37.53 | N31: 否 | W31: 936580188427 | X31: 顺丰包邮卡士007酸奶原味1kg大瓶益生菌健身代餐风味发酵乳家庭装 | Y31: 口味:007益生菌原味1kg;罐数:1瓶 | Z31: 5828280197090 | AA31: =J31*L31 -> 24.9 | AB31: =K:K-AA:AA -> 12.63
A32: 46082 | B32: 46084 | C32: 华东大区 | D32: 未知经销商 | E32: 淘宝/天猫 | F32: 江苏苏州 | G32: CLASSYKISS乳品线上店 | H32: https://item.taobao.com/item.htm?id=976718887462 | I32: 卡士007AD钙益生菌酸奶-果味-210g | J32: 6 | K32: 67.87 | L32: =VLOOKUP(I:I,[1]指导价!$A:$B,2,0) -> 8.9 | M32: =K32/J32 -> 11.311667 | N32: 否 | W32: 976718887462 | X32: 顺丰包邮卡士酸奶007草莓树莓蓝莓黑莓味210gAD钙7种活性益生菌 | Y32: 口味:AD钙草莓树莓蓝莓黑莓风味210g*6瓶 | Z32: 6098019162176 | AA32: =J32*L32 -> 53.4 | AB32: =K:K-AA:AA -> 14.47
A33: 46082 | B33: 46084 | C33: 华东大区 | D33: 未知经销商 | E33: 淘宝/天猫 | F33: 江苏苏州 | G33: CLASSYKISS乳品线上店 | H33: https://item.taobao.com/item.htm?id=937138981403 | I33: 卡士007益生菌酸奶原味440g 单瓶 | J33: 3 | K33: 47.3 | L33: =VLOOKUP(I:I,[1]指导价!$A:$B,2,0) -> 9.9 | M33: =K33/J33 -> 15.766667 | N33: 否 | W33: 937138981403 | X33: 顺丰包邮卡士007酸奶原味440g小奶罐益生菌风味发酵乳早餐奶低温 | Y33: 口味:007益生菌原味440g*3瓶 | Z33: 5995872178068 | AA33: =J33*L33 -> 29.7 | AB33: =K:K-AA:AA -> 17.6
A34: 46082 | B34: 46084 | C34: 华东大区 | D34: 未知经销商 | E34: 淘宝/天猫 | F34: 江苏苏州 | G34: CLASSYKISS乳品线上店 | H34: https://item.taobao.com/item.htm?id=985072411981 | I34: 卡士007小瓶装益生菌酸奶原味 220g | J34: 6 | K34: 68.17 | L34: =VLOOKUP(I:I,[1]指导价!$A:$B,2,0) -> 8.9 | M34: =K34/J34 -> 11.361667 | N34: 否 | W34: 985072411981 | X34: 顺丰包邮卡士007酸奶AD钙益生菌牛油果原味莓果蓝草莓早餐儿童奶 | Y34: 口味:AD钙原味小奶罐220g *6瓶 | Z34: 5949496205471 | AA34: =J34*L34 -> 53.4 | AB34: =K:K-AA:AA -> 14.77
A35: 46082 | B35: 46084 | C35: 华东大区 | D35: 未知经销商 | E35: 淘宝/天猫 | F35: 江苏苏州 | G35: CLASSYKISS乳品线上店 | H35: https://item.taobao.com/item.htm?id=938694055816 | I35: 卡士007小瓶装益生菌酸奶原味 220g | J35: 3 | K35: 43.43 | L35: =VLOOKUP(I:I,[1]指导价!$A:$B,2,0) -> 8.9 | M35: =K35/J35 -> 14.476667 | N35: 否 | W35: 938694055816 | X35: 顺丰包邮低温卡士酸奶007AD钙益生菌原味220g营养早餐奶儿童 | Y35: 口味:AD钙原味220g *3瓶 | Z35: 5836407909919 | AA35: =J35*L35 -> 26.7 | AB35: =K:K-AA:AA -> 16.73
A36: 46082 | B36: 46084 | C36: 华东大区 | D36: 未知经销商 | E36: 淘宝/天猫 | F36: 江苏苏州 | G36: CLASSYKISS乳品线上店 | H36: https://item.taobao.com/item.htm?id=936108075223 | I36: 卡士007无蔗糖益生菌酸奶原味428g 单瓶 | J36: 3 | K36: 47.24 | L36: =VLOOKUP(I:I,[1]指导价!$A:$B,2,0) -> 9.9 | M36: =K36/J36 -> 15.746667 | N36: 否 | W36: 936108075223 | X36: 顺丰包邮卡士007酸奶零无蔗糖428g小奶罐益生菌风味发酵乳早餐奶 | Y36: 口味:007益生菌零蔗糖428g*3瓶 | Z36: 5996981219826 | AA36: =J36*L36 -> 29.7 | AB36: =K:K-AA:AA -> 17.54
A37: 46082 | B37: 46084 | C37: 华东大区 | D37: 未知经销商 | E37: 淘宝/天猫 | F37: 江苏苏州 | G37: CLASSYKISS乳品线上店 | H37: https://item.taobao.com/item.htm?id=996625380805 | I37: 卡士007益生菌酸奶原味440g 单瓶 | J37: 3 | K37: 47.52 | L37: =VLOOKUP(I:I,[1]指导价!$A:$B,2,0) -> 9.9 | M37: =K37/J37 -> 15.84 | N37: 否 | W37: 996625380805 | X37: 顺丰包邮卡士酸奶007益生菌零0蔗糖428g早餐奶原味440g小奶罐969g | Y37: 口味:007益生菌原味440g*3瓶 | Z37: 6140492270811 | AA37: =J37*L37 -> 29.7 | AB37: =K:K-AA:AA -> 17.82
A38: 46082 | B38: 46084 | C38: 华东大区 | D38: 未知经销商 | E38: 淘宝/天猫 | F38: 江苏苏州 | G38: CLASSYKISS乳品线上店 | H38: https://item.taobao.com/item.htm?id=989034544143 | I38: 卡士007小瓶装益生菌酸奶原味 220g | J38: 6 | K38: 68.52 | L38: =VLOOKUP(I:I,[1]指导价!$A:$B,2,0) -> 8.9 | M38: =K38/J38 -> 11.42 | N38: 否 | W38: 989034544143 | X38: 顺丰包邮卡士007酸奶小奶罐AD钙益生菌牛油果原味莓果早餐儿童奶 | Y38: 口味:AD钙原味小奶罐220g *6瓶 | Z38: 6119277219491 | AA38: =J38*L38 -> 53.4 | AB38: =K:K-AA:AA -> 15.12
A39: 46082 | B39: 46084 | C39: 华东大区 | D39: 未知经销商 | E39: 淘宝/天猫 | F39: 江苏苏州 | G39: CLASSYKISS乳品线上店 | H39: https://item.taobao.com/item.htm?id=948127298948 | I39: 卡士007益生菌酸奶原味440g 单瓶 | J39: 3 | K39: 47.64 | L39: =VLOOKUP(I:I,[1]指导价!$A:$B,2,0) -> 9.9 | M39: =K39/J39 -> 15.88 | N39: 否 | W39: 948127298948 | X39: 顺丰包邮卡士酸奶007益生菌零0蔗糖428g早餐奶原味440g小奶罐969g | Y39: 口味:007益生菌原味440g*3瓶 | Z39: 6026027795589 | AA39: =J39*L39 -> 29.7 | AB39: =K:K-AA:AA -> 17.94
A40: 46082 | B40: 46084 | C40: =VLOOKUP(G40,白名单!C:E,3,0) -> 广州大区 | D40: =VLOOKUP(G40,白名单!C:F,4,0) -> 广州喜万佳便利店有限公司 | E40: 淘宝/天猫 | F40: 广东广州 | G40: classykiss乳业企业店 | H40: https://item.taobao.com/item.htm?id=659965095188 | I40: 卡士007无蔗糖益生菌家庭装酸奶原味969g 单瓶 | J40: 1 | K40: 29.8 | L40: =VLOOKUP(I:I,[1]指导价!$A:$B,2,0) -> 24.9 | M40: =K40/J40 -> 29.8 | N40: 否 | V40: 满20.0减6.0；满20减6；淘金币频道抵扣1%起；店铺券 | 满20减6；店铺券 | 满20减6 | W40: 659965095188 | X40: 卡士007无蔗糖969g家庭装原味酸奶益生菌0蔗糖风味发酵乳控糖代餐 | Y40: 【1瓶】家庭装0蔗糖969g | Z40: 5843771142247 | AA40: =J40*L40 -> 24.9 | AB40: =K:K-AA:AA -> 4.9
...

Sheet 违规数据
A1: 年月 | B1: 核检日期 | C1: 所属大区 | D1: 更新经销商 | E1: 平台名称 | F1: 发货地区 | G1: 序号 | H1: 店铺名称 | I1: 商品链接 | J1: 型号 | K1: 数量 | L1: 平台促销价 | M1: 2026年1月促销价格指引 | N1: 售卖单价 （PC） | O1: 促销价是否比红线价低 | P1: 处理大区 | Q1: 负责人 | R1: 整改时间 | S1: 反馈整改图片 | T1: 谁处理问题 | U1: 处理时间 | V1: 处理结果 | W1: 优惠信息 | X1: 商品ID | Y1: spu名称 | Z1: sku描述 | AA1: skuid | AB1: 换算价 | AC1: 差价 | AD1: 正常价 | AE1: 销量
A2: 46082 | B2: 46084 | C2: 广州大区 | D2: 未知经销商 | E2: 淘宝/天猫 | F2: 广东 东莞 | G2: 1 | H2: classykiss卡士宫荼专卖店 | I2: https://item.taobao.com/item.htm?id=1016348664448 | J2: 卡士吃酸大果粒风味发酵乳系列(黄桃、酸木瓜、粉芭乐）3联 | K2: 4 | L2: 129 | M2: 32.9 | N2: 32.25 | O2: 是 | U2: 46085 | V2: 未调整 | X2: 1016348664448 | Y2: 卡士酸奶吃酸风味发酵乳140g*12杯芭乐柠檬水蜜桃酸木瓜黄桃酸奶 | Z2: 商品规格:12杯】酸木瓜双柚芦荟味 | AA2: 6186233958349 | AB2: 131.6 | AC2: -2.6 | AD2: 129
A3: 46082 | B3: 46084 | C3: 广州大区 | D3: 未知经销商 | E3: 淘宝/天猫 | F3: 广东 东莞 | G3: 2 | H3: classykiss卡士宫荼专卖店 | I3: https://item.taobao.com/item.htm?id=1016348664448 | J3: 卡士吃酸大果粒风味发酵乳系列(黄桃、酸木瓜、粉芭乐）3联 | K3: 4 | L3: 129 | M3: 32.9 | N3: 32.25 | O3: 是 | U3: 46085 | V3: 未调整 | X3: 1016348664448 | Y3: 卡士酸奶吃酸风味发酵乳140g*12杯芭乐柠檬水蜜桃酸木瓜黄桃酸奶 | Z3: 商品规格:12杯】黄杏黄桃话梅味 | AA3: 6186233958350 | AB3: 131.6 | AC3: -2.6 | AD3: 129
A4: 46082 | B4: 46084 | C4: 广州大区 | D4: 未知经销商 | E4: 淘宝/天猫 | F4: 广东 东莞 | G4: 3 | H4: classykiss卡士宫荼专卖店 | I4: https://item.taobao.com/item.htm?id=1016348664448 | J4: 卡士吃酸大果粒风味发酵乳系列(黄桃、酸木瓜、粉芭乐）3联 | K4: 4 | L4: 129 | M4: 32.9 | N4: 32.25 | O4: 是 | U4: 46085 | V4: 未调整 | X4: 1016348664448 | Y4: 卡士酸奶吃酸风味发酵乳140g*12杯芭乐柠檬水蜜桃酸木瓜黄桃酸奶 | Z4: 商品规格:12杯】芭乐柠檬水蜜桃味 | AA4: 6186233958348 | AB4: 131.6 | AC4: -2.6 | AD4: 129
A5: 46082 | B5: 46084 | C5: 广州大区 | D5: 未知经销商 | E5: 淘宝/天猫 | F5: 广东 东莞 | G5: 4 | H5: classykiss卡士宫荼专卖店 | I5: https://item.taobao.com/item.htm?id=891449603394 | J5: 卡士断糖日记无蔗糖原味130g 单瓶 | K5: 12 | L5: 85.07 | M5: 7.4 | N5: 7.0891667 | O5: 是 | U5: 46085 | V5: 未调整 | X5: 891449603394 | Y5: 卡士酸奶断糖日记无蔗糖发酵乳原味含益生菌代餐奶低温130g* 8杯 | Z5: 口味:6杯原味+6杯椰子味 | AA5: 5841937516523 | AB5: 88.8 | AC5: -3.73 | AD5: 85.07
A6: 46082 | B6: 46084 | C6: 广州大区 | D6: 未知经销商 | E6: 淘宝/天猫 | F6: 广东 东莞 | G6: 5 | H6: classykiss卡士宫荼专卖店 | I6: https://item.taobao.com/item.htm?id=891449603394 | J6: 卡士断糖日记无蔗糖原味130g 单瓶 | K6: 36 | L6: 232 | M6: 7.4 | N6: 6.4444444 | O6: 是 | U6: 46085 | V6: 未调整 | X6: 891449603394 | Y6: 卡士酸奶断糖日记无蔗糖发酵乳原味含益生菌代餐奶低温130g* 8杯 | Z6: 口味:36杯】断糖原味 | AA6: 5905497694047 | AB6: 266.4 | AC6: -34.4 | AD6: 232
A7: 46082 | B7: 46084 | C7: 广州大区 | D7: 未知经销商 | E7: 淘宝/天猫 | F7: 广东 东莞 | G7: 6 | H7: classykiss卡士宫荼专卖店 | I7: https://item.taobao.com/item.htm?id=891449603394 | J7: 卡士断糖日记无蔗糖原味130g 单瓶 | K7: 36 | L7: 232 | M7: 7.4 | N7: 6.4444444 | O7: 是 | U7: 46085 | V7: 未调整 | X7: 891449603394 | Y7: 卡士酸奶断糖日记无蔗糖发酵乳原味含益生菌代餐奶低温130g* 8杯 | Z7: 口味:36杯】断糖椰子味 | AA7: 5841937516521 | AB7: 266.4 | AC7: -34.4 | AD7: 232
A8: 46082 | B8: 46084 | C8: 广州大区 | D8: 未知经销商 | E8: 淘宝/天猫 | F8: 广东 东莞 | G8: 7 | H8: classykiss卡士宫荼专卖店 | I8: https://item.taobao.com/item.htm?id=891449603394 | J8: 卡士断糖日记无蔗糖原味130g 单瓶 | K8: 24 | L8: 154.67 | M8: 7.4 | N8: 6.4445833 | O8: 是 | U8: 46085 | V8: 未调整 | X8: 891449603394 | Y8: 卡士酸奶断糖日记无蔗糖发酵乳原味含益生菌代餐奶低温130g* 8杯 | Z8: 口味:24杯】断糖原味 | AA8: 5905497694046 | AB8: 177.6 | AC8: -22.93 | AD8: 154.67
A9: 46082 | B9: 46084 | C9: 广州大区 | D9: 未知经销商 | E9: 淘宝/天猫 | F9: 广东 东莞 | G9: 8 | H9: classykiss卡士宫荼专卖店 | I9: https://item.taobao.com/item.htm?id=891449603394 | J9: 卡士断糖日记无蔗糖原味130g 单瓶 | K9: 24 | L9: 154.67 | M9: 7.4 | N9: 6.4445833 | O9: 是 | U9: 46085 | V9: 未调整 | X9: 891449603394 | Y9: 卡士酸奶断糖日记无蔗糖发酵乳原味含益生菌代餐奶低温130g* 8杯 | Z9: 口味:24杯】断糖椰子味 | AA9: 5841937516520 | AB9: 177.6 | AC9: -22.93 | AD9: 154.67
A10: 46082 | B10: 46084 | C10: 广州大区 | D10: 未知经销商 | E10: 淘宝/天猫 | F10: 广东东莞 | G10: 9 | H10: classykiss卡士宫荼专卖店 | I10: https://detail.tmall.com/item.htm?id=969375047856 | J10: 卡士餐后一小时原味250g | K10: 24 | L10: 260 | M10: 10.9 | N10: 10.833333 | O10: 是 | U10: 46085 | V10: 未调整 | W10: 购买得积分 | X10: 969375047856 | Y10: 卡士酸奶餐后一小时风味发酵乳益生菌酸奶整箱250g*8瓶 | Z10: 24瓶】有甜味餐后一小时 | AA10: 6084922134156 | AB10: 261.6 | AC10: -1.6 | AD10: 260 | AE10: 5
A11: 46082 | B11: 46084 | C11: 广州大区 | D11: 未知经销商 | E11: 淘宝/天猫 | F11: 广东 东莞 | G11: 10 | H11: classykiss卡士宫荼专卖店 | I11: https://item.taobao.com/item.htm?id=891449603394 | J11: 卡士断糖日记无蔗糖原味130g 单瓶 | K11: 12 | L11: 85.07 | M11: 7.4 | N11: 7.0891667 | O11: 是 | U11: 46085 | V11: 未调整 | X11: 891449603394 | Y11: 卡士酸奶断糖日记无蔗糖发酵乳原味含益生菌代餐奶低温130g* 8杯 | Z11: 口味:12杯】断糖原味 | AA11: 5905497694045 | AB11: 88.8 | AC11: -3.73 | AD11: 85.07
A12: 46082 | B12: 46084 | C12: 广州大区 | D12: 未知经销商 | E12: 淘宝/天猫 | F12: 广东 东莞 | G12: 11 | H12: classykiss卡士宫荼专卖店 | I12: https://item.taobao.com/item.htm?id=891449603394 | J12: 卡士断糖日记无蔗糖原味130g 单瓶 | K12: 12 | L12: 85.07 | M12: 7.4 | N12: 7.0891667 | O12: 是 | U12: 46085 | V12: 未调整 | X12: 891449603394 | Y12: 卡士酸奶断糖日记无蔗糖发酵乳原味含益生菌代餐奶低温130g* 8杯 | Z12: 口味:12杯】断糖椰子味 | AA12: 5841937516522 | AB12: 88.8 | AC12: -3.73 | AD12: 85.07
A13: 46082 | B13: 46084 | C13: 广州大区 | D13: 未知经销商 | E13: 淘宝/天猫 | F13: 广东东莞 | G13: 12 | H13: classykiss卡士宫荼专卖店 | I13: https://detail.tmall.com/item.htm?id=891449603394 | J13: 卡士断糖日记无蔗糖原味130g 单瓶 | K13: 24 | L13: 145 | M13: 7.4 | N13: 6.0416667 | O13: 是 | U13: 46085 | V13: 未调整 | W13: 店铺新客减3元 | X13: 891449603394 | Y13: 卡士酸奶断糖日记无蔗糖发酵乳原味含益生菌代餐奶低温130g* 8杯 | Z13: 24杯】断糖椰子味 | AA13: 5841937516520 | AB13: 177.6 | AC13: -32.6 | AD13: 156 | AE13: 3000+
A14: 46082 | B14: 46084 | C14: 广州大区 | D14: 未知经销商 | E14: 淘宝/天猫 | F14: 广东东莞 | G14: 13 | H14: classykiss卡士宫荼专卖店 | I14: https://detail.tmall.com/item.htm?id=891449603394 | J14: 卡士断糖日记无蔗糖原味130g 单瓶 | K14: 36 | L14: 217 | M14: 7.4 | N14: 6.0277778 | O14: 是 | U14: 46085 | V14: 未调整 | W14: 店铺新客减3元 | X14: 891449603394 | Y14: 卡士酸奶断糖日记无蔗糖发酵乳原味含益生菌代餐奶低温130g* 8杯 | Z14: 36杯】断糖椰子味 | AA14: 5841937516521 | AB14: 266.4 | AC14: -49.4 | AD14: 232 | AE14: 3000+
A15: 46082 | B15: 46084 | C15: 广州大区 | D15: 未知经销商 | E15: 淘宝/天猫 | F15: 广东东莞 | G15: 14 | H15: classykiss卡士宫荼专卖店 | I15: https://detail.tmall.com/item.htm?id=891449603394 | J15: 卡士断糖日记无蔗糖原味130g 单瓶 | K15: 12 | L15: 75 | M15: 7.4 | N15: 6.25 | O15: 是 | U15: 46085 | V15: 未调整 | W15: 店铺新客减3元 | X15: 891449603394 | Y15: 卡士酸奶断糖日记无蔗糖发酵乳原味含益生菌代餐奶低温130g* 8杯 | Z15: 12杯】断糖椰子味 | AA15: 5841937516522 | AB15: 88.8 | AC15: -13.8 | AD15: 79 | AE15: 3000+
A16: 46082 | B16: 46084 | C16: 广州大区 | D16: 未知经销商 | E16: 淘宝/天猫 | F16: 广东东莞 | G16: 15 | H16: classykiss卡士宫荼专卖店 | I16: https://detail.tmall.com/item.htm?id=891449603394 | J16: 卡士断糖日记无蔗糖原味130g 单瓶 | K16: 12 | L16: 75 | M16: 7.4 | N16: 6.25 | O16: 是 | U16: 46085 | V16: 未调整 | W16: 店铺新客减3元 | X16: 891449603394 | Y16: 卡士酸奶断糖日记无蔗糖发酵乳原味含益生菌代餐奶低温130g* 8杯 | Z16: 6杯原味+6杯椰子味 | AA16: 5841937516523 | AB16: 88.8 | AC16: -13.8 | AD16: 79 | AE16: 3000+
A17: 46082 | B17: 46084 | C17: 广州大区 | D17: 未知经销商 | E17: 淘宝/天猫 | F17: 广东东莞 | G17: 16 | H17: classykiss卡士宫荼专卖店 | I17: https://detail.tmall.com/item.htm?id=891449603394 | J17: 卡士断糖日记无蔗糖原味130g 单瓶 | K17: 24 | L17: 145 | M17: 7.4 | N17: 6.0416667 | O17: 是 | U17: 46085 | V17: 未调整 | W17: 店铺新客减3元 | X17: 891449603394 | Y17: 卡士酸奶断糖日记无蔗糖发酵乳原味含益生菌代餐奶低温130g* 8杯 | Z17: 12杯原味+12杯椰子味 | AA17: 5841937516524 | AB17: 177.6 | AC17: -32.6 | AD17: 156 | AE17: 3000+
A18: 46082 | B18: 46084 | C18: 广州大区 | D18: 未知经销商 | E18: 淘宝/天猫 | F18: 广东东莞 | G18: 17 | H18: classykiss卡士宫荼专卖店 | I18: https://detail.tmall.com/item.htm?id=891449603394 | J18: 卡士断糖日记无蔗糖原味130g 单瓶 | K18: 36 | L18: 217 | M18: 7.4 | N18: 6.0277778 | O18: 是 | U18: 46085 | V18: 未调整 | W18: 店铺新客减3元 | X18: 891449603394 | Y18: 卡士酸奶断糖日记无蔗糖发酵乳原味含益生菌代餐奶低温130g* 8杯 | Z18: 18杯原味+18杯椰子味 | AA18: 5841937516525 | AB18: 266.4 | AC18: -49.4 | AD18: 232 | AE18: 3000+
A19: 46082 | B19: 46084 | C19: 广州大区 | D19: 未知经销商 | E19: 淘宝/天猫 | F19: 广东东莞 | G19: 18 | H19: classykiss卡士宫荼专卖店 | I19: https://detail.tmall.com/item.htm?id=891449603394 | J19: 卡士断糖日记无蔗糖原味130g 单瓶 | K19: 12 | L19: 75 | M19: 7.4 | N19: 6.25 | O19: 是 | U19: 46085 | V19: 未调整 | W19: 店铺新客减3元 | X19: 891449603394 | Y19: 卡士酸奶断糖日记无蔗糖发酵乳原味含益生菌代餐奶低温130g* 8杯 | Z19: 12杯】断糖原味 | AA19: 5905497694045 | AB19: 88.8 | AC19: -13.8 | AD19: 79 | AE19: 3000+
A20: 46082 | B20: 46084 | C20: 广州大区 | D20: 未知经销商 | E20: 淘宝/天猫 | F20: 广东东莞 | G20: 19 | H20: classykiss卡士宫荼专卖店 | I20: https://detail.tmall.com/item.htm?id=891449603394 | J20: 卡士断糖日记无蔗糖原味130g 单瓶 | K20: 24 | L20: 145 | M20: 7.4 | N20: 6.0416667 | O20: 是 | U20: 46085 | V20: 未调整 | W20: 店铺新客减3元 | X20: 891449603394 | Y20: 卡士酸奶断糖日记无蔗糖发酵乳原味含益生菌代餐奶低温130g* 8杯 | Z20: 24杯】断糖原味 | AA20: 5905497694046 | AB20: 177.6 | AC20: -32.6 | AD20: 156 | AE20: 3000+
A21: 46082 | B21: 46084 | C21: 广州大区 | D21: 未知经销商 | E21: 淘宝/天猫 | F21: 广东东莞 | G21: 20 | H21: classykiss卡士宫荼专卖店 | I21: https://detail.tmall.com/item.htm?id=891449603394 | J21: 卡士断糖日记无蔗糖原味130g 单瓶 | K21: 36 | L21: 217 | M21: 7.4 | N21: 6.0277778 | O21: 是 | U21: 46085 | V21: 未调整 | W21: 店铺新客减3元 | X21: 891449603394 | Y21: 卡士酸奶断糖日记无蔗糖发酵乳原味含益生菌代餐奶低温130g* 8杯 | Z21: 36杯】断糖原味 | AA21: 5905497694047 | AB21: 266.4 | AC21: -49.4 | AD21: 232 | AE21: 3000+
A22: 46082 | B22: 46084 | C22: 广州大区 | D22: 未知经销商 | E22: 淘宝/天猫 | F22: 广东东莞 | G22: 21 | H22: classykiss卡士宫荼专卖店 | I22: https://detail.tmall.com/item.htm?id=891449603394 | J22: 卡士断糖日记无蔗糖原味130g 单瓶 | K22: 8 | L22: 56 | M22: 7.4 | N22: 7 | O22: 是 | U22: 46085 | V22: 未调整 | W22: 店铺新客减3元 | X22: 891449603394 | Y22: 卡士酸奶断糖日记无蔗糖发酵乳原味含益生菌代餐奶低温130g* 8杯 | Z22: 8杯】断糖原味 | AA22: 6114287170186 | AB22: 59.2 | AC22: -3.2 | AD22: 59 | AE22: 3000+
A23: 46082 | B23: 46084 | C23: 广州大区 | D23: 未知经销商 | E23: 淘宝/天猫 | F23: 广东东莞 | G23: 22 | H23: classykiss卡士宫荼专卖店 | I23: https://detail.tmall.com/item.htm?id=901960799069 | J23: 卡士断糖日记无蔗糖原味130g 单瓶 | K23: 12 | L23: 79.9 | M23: 7.4 | N23: 6.6583333 | O23: 是 | U23: 46085 | V23: 未调整 | W23: 购买得积分 | X23: 901960799069 | Y23: 卡士酸奶断糖日记椰子味无蔗糖风味发酵乳低温冷藏130g/杯*8杯 | Z23: 12杯】断糖椰子味 | AA23: 5759319460991 | AB23: 88.8 | AC23: -8.9 | AD23: 79.9 | AE23: 72
A24: 46082 | B24: 46084 | C24: 广州大区 | D24: 未知经销商 | E24: 淘宝/天猫 | F24: 广东东莞 | G24: 23 | H24: classykiss卡士宫荼专卖店 | I24: https://detail.tmall.com/item.htm?id=901960799069 | J24: 卡士断糖日记无蔗糖原味130g 单瓶 | K24: 24 | L24: 158.9 | M24: 7.4 | N24: 6.6208333 | O24: 是 | U24: 46085 | V24: 未调整 | W24: 购买得积分 | X24: 901960799069 | Y24: 卡士酸奶断糖日记椰子味无蔗糖风味发酵乳低温冷藏130g/杯*8杯 | Z24: 24杯】断糖椰子味 | AA24: 5759319460992 | AB24: 177.6 | AC24: -18.7 | AD24: 158.9 | AE24: 72
A25: 46082 | B25: 46084 | C25: 广州大区 | D25: 未知经销商 | E25: 淘宝/天猫 | F25: 广东东莞 | G25: 24 | H25: classykiss卡士宫荼专卖店 | I25: https://detail.tmall.com/item.htm?id=901960799069 | J25: 卡士断糖日记无蔗糖原味130g 单瓶 | K25: 12 | L25: 79.9 | M25: 7.4 | N25: 6.6583333 | O25: 是 | U25: 46085 | V25: 未调整 | W25: 购买得积分 | X25: 901960799069 | Y25: 卡士酸奶断糖日记椰子味无蔗糖风味发酵乳低温冷藏130g/杯*8杯 | Z25: 12杯】断糖原味 | AA25: 5942974966952 | AB25: 88.8 | AC25: -8.9 | AD25: 79.9 | AE25: 72
A26: 46082 | B26: 46084 | C26: 广州大区 | D26: 未知经销商 | E26: 淘宝/天猫 | F26: 广东东莞 | G26: 25 | H26: classykiss卡士宫荼专卖店 | I26: https://detail.tmall.com/item.htm?id=901960799069 | J26: 卡士断糖日记无蔗糖原味130g 单瓶 | K26: 24 | L26: 158.9 | M26: 7.4 | N26: 6.6208333 | O26: 是 | U26: 46085 | V26: 未调整 | W26: 购买得积分 | X26: 901960799069 | Y26: 卡士酸奶断糖日记椰子味无蔗糖风味发酵乳低温冷藏130g/杯*8杯 | Z26: 24杯】断糖原味 | AA26: 5942974966953 | AB26: 177.6 | AC26: -18.7 | AD26: 158.9 | AE26: 72
A27: 46082 | B27: 46084 | C27: 广州大区 | D27: 未知经销商 | E27: 淘宝/天猫 | F27: 广东东莞 | G27: 26 | H27: classykiss卡士宫荼专卖店 | I27: https://detail.tmall.com/item.htm?id=901960799069 | J27: 卡士断糖日记无蔗糖原味130g 单瓶 | K27: 12 | L27: 79.9 | M27: 7.4 | N27: 6.6583333 | O27: 是 | U27: 46085 | V27: 未调整 | W27: 购买得积分 | X27: 901960799069 | Y27: 卡士酸奶断糖日记椰子味无蔗糖风味发酵乳低温冷藏130g/杯*8杯 | Z27: 原味6杯+椰子味6杯 | AA27: 5942974966955 | AB27: 88.8 | AC27: -8.9 | AD27: 79.9 | AE27: 72
A28: 46082 | B28: 46084 | C28: 广州大区 | D28: 未知经销商 | E28: 淘宝/天猫 | F28: 广东东莞 | G28: 27 | H28: classykiss卡士宫荼专卖店 | I28: https://detail.tmall.com/item.htm?id=901960799069 | J28: 卡士断糖日记无蔗糖原味130g 单瓶 | K28: 24 | L28: 158.9 | M28: 7.4 | N28: 6.6208333 | O28: 是 | U28: 46085 | V28: 未调整 | W28: 购买得积分 | X28: 901960799069 | Y28: 卡士酸奶断糖日记椰子味无蔗糖风味发酵乳低温冷藏130g/杯*8杯 | Z28: 原味12杯+椰子味12杯 | AA28: 5942974966956 | AB28: 177.6 | AC28: -18.7 | AD28: 158.9 | AE28: 72
A29: 46082 | B29: 46084 | C29: 广州大区 | D29: 未知经销商 | E29: 淘宝/天猫 | F29: 广东东莞 | G29: 28 | H29: classykiss卡士宫荼专卖店 | I29: https://detail.tmall.com/item.htm?id=892370854388 | J29: 卡士餐后一小时原味250g | K29: 8 | L29: 84 | M29: 10.9 | N29: 10.5 | O29: 是 | U29: 46085 | V29: 未调整 | W29: 店铺新客减4元 | X29: 892370854388 | Y29: 卡士酸奶餐后一小时风味发酵乳益生菌酸奶整箱250g*8瓶 | Z29: 8瓶】有甜味餐后一小时 | AA29: 5907167610155 | AB29: 87.2 | AC29: -3.2 | AD29: 88 | AE29: 1000+
A30: 46082 | B30: 46084 | C30: 广州大区 | D30: 未知经销商 | E30: 淘宝/天猫 | F30: 广东东莞 | G30: 29 | H30: classykiss卡士宫荼专卖店 | I30: https://detail.tmall.com/item.htm?id=892370854388 | J30: 卡士餐后一小时原味250g | K30: 8 | L30: 84 | M30: 10.9 | N30: 10.5 | O30: 是 | U30: 46085 | V30: 未调整 | W30: 店铺新客减4元 | X30: 892370854388 | Y30: 卡士酸奶餐后一小时风味发酵乳益生菌酸奶整箱250g*8瓶 | Z30: 8瓶】0蔗糖餐后一小时 | AA30: 5907167610156 | AB30: 87.2 | AC30: -3.2 | AD30: 88 | AE30: 1000+
A31: 46082 | B31: 46084 | C31: 广州大区 | D31: 未知经销商 | E31: 淘宝/天猫 | F31: 广东东莞 | G31: 30 | H31: classykiss卡士宫荼专卖店 | I31: https://detail.tmall.com/item.htm?id=892370854388 | J31: 卡士餐后一小时原味250g | K31: 24 | L31: 247 | M31: 10.9 | N31: 10.291667 | O31: 是 | U31: 46085 | V31: 未调整 | W31: 店铺新客减4元 | X31: 892370854388 | Y31: 卡士酸奶餐后一小时风味发酵乳益生菌酸奶整箱250g*8瓶 | Z31: 24瓶】有甜味餐后一小时 | AA31: 5907167610159 | AB31: 261.6 | AC31: -14.6 | AD31: 262 | AE31: 1000+
A32: 46082 | B32: 46084 | C32: 广州大区 | D32: 未知经销商 | E32: 淘宝/天猫 | F32: 广东东莞 | G32: 31 | H32: classykiss卡士宫荼专卖店 | I32: https://detail.tmall.com/item.htm?id=969375047856 | J32: 卡士餐后一小时原味250g | K32: 24 | L32: 260 | M32: 10.9 | N32: 10.833333 | O32: 是 | U32: 46085 | V32: 未调整 | W32: 购买得积分 | X32: 969375047856 | Y32: 卡士酸奶餐后一小时风味发酵乳益生菌酸奶整箱250g*8瓶 | Z32: 24瓶】0蔗糖餐后一小时 | AA32: 6084922134157 | AB32: 261.6 | AC32: -1.6 | AD32: 260 | AE32: 5
A33: 46082 | B33: 46084 | C33: 广州大区 | D33: 未知经销商 | E33: 淘宝/天猫 | F33: 广东东莞 | G33: 32 | H33: classykiss卡士宫荼专卖店 | I33: https://detail.tmall.com/item.htm?id=892370854388 | J33: 卡士餐后一小时原味250g | K33: 24 | L33: 247 | M33: 10.9 | N33: 10.291667 | O33: 是 | U33: 46085 | V33: 未调整 | W33: 店铺新客减4元 | X33: 892370854388 | Y33: 卡士酸奶餐后一小时风味发酵乳益生菌酸奶整箱250g*8瓶 | Z33: 24瓶】0蔗糖餐后一小时 | AA33: 5907167610160 | AB33: 261.6 | AC33: -14.6 | AD33: 262 | AE33: 1000+
A34: 46082 | B34: 46084 | C34: 广州大区 | D34: 广州喜万佳便利店有限公司 | E34: 淘宝/天猫 | F34: 广东 广州 | G34: 33 | H34: CLASSYKISS乳品企业店 | I34: https://item.taobao.com/item.htm?id=827561688204 | J34: 卡士007小瓶装益生菌酸奶原味 220g | K34: 10 | L34: 88.8 | M34: 8.9 | N34: 8.88 | O34: 是 | X34: 827561688204 | Y34: 卡士酸奶200ml低温生牛乳活性益生菌酸牛奶孕妇学生早餐奶盒装 | Z34: 口味:【10瓶】活菌奶220g | AA34: 5957088824933 | AB34: 89 | AC34: -0.2 | AD34: 88.8
A35: 46082 | B35: 46084 | C35: 广州大区 | D35: 广州喜万佳便利店有限公司 | E35: 淘宝/天猫 | F35: 广东广州 | G35: 34 | H35: CLASSYKISS乳品企业店 | I35: https://item.taobao.com/item.htm?id=994962638547 | J35: 卡士吃酸大果粒风味发酵乳系列(黄桃、酸木瓜、粉芭乐）3联 | K35: 4 | L35: 99.8 | M35: 32.9 | N35: 24.95 | O35: 是 | W35: 券满20减6 | X35: 994962638547 | Y35: 卡士酸奶吃酸140g芭乐柠檬水蜜桃酸木瓜黄桃大颗果肉风味发酵乳 | Z35: 【12杯】芭乐柠檬水蜜桃味140g | AA35: 6140728403290 | AB35: 131.6 | AC35: -31.8 | AD35: 105.8 | AE35: 300+
A36: 46082 | B36: 46084 | C36: 广州大区 | D36: 广州喜万佳便利店有限公司 | E36: 淘宝/天猫 | F36: 广东广州 | G36: 35 | H36: CLASSYKISS乳品企业店 | I36: https://item.taobao.com/item.htm?id=994962638547 | J36: 卡士吃酸大果粒风味发酵乳系列(黄桃、酸木瓜、粉芭乐）3联 | K36: 4 | L36: 99.8 | M36: 32.9 | N36: 24.95 | O36: 是 | W36: 券满20减6 | X36: 994962638547 | Y36: 卡士酸奶吃酸140g芭乐柠檬水蜜桃酸木瓜黄桃大颗果肉风味发酵乳 | Z36: 【12杯】酸木瓜双柚芦荟味140g | AA36: 6140728403293 | AB36: 131.6 | AC36: -31.8 | AD36: 105.8 | AE36: 300+
A37: 46082 | B37: 46084 | C37: 广州大区 | D37: 广州喜万佳便利店有限公司 | E37: 淘宝/天猫 | F37: 广东广州 | G37: 36 | H37: CLASSYKISS乳品企业店 | I37: https://item.taobao.com/item.htm?id=994962638547 | J37: 卡士吃酸大果粒风味发酵乳系列(黄桃、酸木瓜、粉芭乐）3联 | K37: 4 | L37: 99.8 | M37: 32.9 | N37: 24.95 | O37: 是 | W37: 券满20减6 | X37: 994962638547 | Y37: 卡士酸奶吃酸140g芭乐柠檬水蜜桃酸木瓜黄桃大颗果肉风味发酵乳 | Z37: 【12杯】黄杏黄桃话梅味140g | AA37: 6140728403296 | AB37: 131.6 | AC37: -31.8 | AD37: 105.8 | AE37: 300+
A38: 46082 | B38: 46084 | C38: 华东大区 | D38: 未知经销商 | E38: 淘宝/天猫 | F38: 江苏苏州 | G38: 37 | H38: CLASSYKISS乳品线上店 | I38: https://item.taobao.com/item.htm?id=968762108303 | J38: 卡士007AD钙益生菌酸奶-果味-210g | K38: 6 | L38: 51.42 | M38: 8.9 | N38: 8.57 | O38: 是 | U38: 46085 | V38: 已调整 | W38: 官方立减12%省8元；限时立减4.6元 | X38: 968762108303 | Y38: 顺丰包邮卡士AD钙酸奶牛油果青苹果味小奶罐益生菌儿童早餐奶210g | Z38: AD钙益生菌酸奶牛油果味210g*6瓶 | AA38: 5915743941062 | AB38: 53.4 | AC38: -1.98 | AD38: 66 | AE38: 8
A39: 46082 | B39: 46084 | C39: 华东大区 | D39: 未知经销商 | E39: 淘宝/天猫 | F39: 江苏苏州 | G39: 38 | H39: CLASSYKISS乳品线上店 | I39: https://item.taobao.com/item.htm?id=968762108303 | J39: 卡士007AD钙益生菌酸奶-果味-210g | K39: 9 | L39: 77.25 | M39: 8.9 | N39: 8.5833333 | O39: 是 | U39: 46085 | V39: 已调整 | W39: 官方立减12%省8元；限时立减4.6元 | X39: 968762108303 | Y39: 顺丰包邮卡士AD钙酸奶牛油果青苹果味小奶罐益生菌儿童早餐奶210g | Z39: AD钙益生菌酸奶牛油果味210g*9瓶 | AA39: 5915743941063 | AB39: 80.1 | AC39: -2.85 | AD39: 95 | AE39: 8
A40: 46082 | B40: 46084 | C40: 华东大区 | D40: 未知经销商 | E40: 淘宝/天猫 | F40: 江苏苏州 | G40: 39 | H40: CLASSYKISS乳品线上店 | I40: https://item.taobao.com/item.htm?id=941523424714 | J40: 卡士断糖日记无蔗糖原味130g 单瓶 | K40: 4 | L40: 28.46 | M40: 7.4 | N40: 7.115 | O40: 是 | U40: 46085 | V40: 已调整 | W40: 官方立减12%省4.6元；限时立减3.8元 | X40: 941523424714 | Y40: 顺丰包邮 卡士酸奶断糖日记130g无蔗糖原味早餐奶发酵乳儿童奶 | Z40: 断糖日记原味130g*4杯 | AA40: 5839392805914 | AB40: 29.6 | AC40: -1.14 | AD40: 38 | AE40: 18
...

Sheet 餐后违规链接
A1: 年月 | B1: 核检日期 | C1: 所属大区 | D1: 更新经销商 | E1: 平台名称 | F1: 发货地区 | G1: 店铺名称 | H1: 商品链接 | I1: 型号 | J1: 数量 | K1: 平台促销价 | L1: 2026年1月促销价格指引 | M1: 售卖单价 （PC） | N1: 促销价是否比红线价低 | O1: 处理大区 | P1: 负责人 | Q1: 整改时间 | R1: 反馈整改图片 | S1: 谁处理问题 | T1: 处理时间 | U1: 处理结果 | V1: 优惠信息 | W1: 商品ID | X1: spu名称 | Y1: sku描述 | Z1: skuid | AA1: 换算价 | AB1: 差价 | AC1: 正常价 | AD1: 销量
A2: 46054 | B2: 46077 | C2: 无法判定大区 | D2: 未知经销商 | E2: 京东 | G2: 玲柔好物店 | H2: http://item.jd.com/10177000430970.html | I2: 卡士餐后一小时原味250g | J2: 3 | K2: 25.7 | L2: 10.9 | M2: 8.5666667 | N2: 是 | T2: 46079 | U2: 已调整 | W2: 10177000430970 | X2: 卡士（CLASSY.KISS）CLASSYKISS 卡士零糖酸奶原味250g3瓶餐后一小时益生菌低温学生奶 0糖餐后一小时250g*1瓶保质 | Y2: 卡士（CLASSY.KISS）CLASSYKISS 卡士零糖酸奶原味250g3瓶餐后一小时益生菌低温学生奶 0糖餐后一小时250g*1瓶保质 | Z2: 10177000430970 | AA2: 32.7 | AB2: -7
A3: 46054 | B3: 46077 | C3: 广州大区 | D3: 广州喜万佳便利店有限公司 | E3: 京东 | G3: 喜万佳甄选店 | H3: http://item.jd.com/10176874331798.html | I3: 卡士餐后一小时原味250g | J3: 8 | K3: 85.8 | L3: 10.9 | M3: 10.725 | N3: 是 | W3: 10176874331798 | X3: 卡士007无蔗糖969g家庭装益生菌风味发酵乳0蔗糖原味全脂早餐奶大瓶装 【8瓶】餐后一小时0蔗糖250g | Y3: 卡士007无蔗糖969g家庭装益生菌风味发酵乳0蔗糖原味全脂早餐奶大瓶装 【8瓶】餐后一小时0蔗糖250g | Z3: 10176874331798 | AA3: 87.2 | AB3: -1.4
A4: 46054 | B4: 46077 | C4: 广州大区 | D4: 广州喜万佳便利店有限公司 | E4: 京东 | G4: 柏赞食品甄选店 | H4: http://item.jd.com/10175773352591.html | I4: 卡士餐后一小时原味250g | J4: 10 | K4: 93.8 | L4: 10.9 | M4: 9.38 | N4: 是 | W4: 10175773352591 | X4: 卡士（CLASSY.KISS）活菌奶720ml低温原味酸奶益生菌生牛乳风味发酵乳孕妇学生酸牛奶 【8瓶】餐后一小时0蔗糖250g | Y4: 卡士（CLASSY.KISS）活菌奶720ml低温原味酸奶益生菌生牛乳风味发酵乳孕妇学生酸牛奶 【8瓶】餐后一小时0蔗糖250g | Z4: 10175773352591 | AA4: 109 | AB4: -15.2
A5: 46054 | B5: 46077 | C5: 无法判定大区 | D5: 未知经销商 | E5: 京东 | G5: 沃途食品店 | H5: http://item.jd.com/10161032513827.html | I5: 卡士餐后一小时原味250g | J5: 8 | K5: 67.5 | L5: 10.9 | M5: 8.4375 | N5: 是 | T5: 46079 | U5: 已调整 | W5: 10161032513827 | X5: 卡士（CLASSY.KISS）酸奶餐后一小时发酵乳250g*12瓶原味营养双歧杆菌风味发酵乳 餐后一小时原味 3瓶 | Y5: 卡士（CLASSY.KISS）酸奶餐后一小时发酵乳250g*12瓶原味营养双歧杆菌风味发酵乳 餐后一小时原味 3瓶 | Z5: 10161032513827 | AA5: 87.2 | AB5: -19.7
A6: 46054 | B6: 46077 | C6: 广州大区 | D6: 广州喜万佳便利店有限公司 | E6: 京东 | G6: 柏赞食品甄选店 | H6: http://item.jd.com/10175735583817.html | I6: 卡士餐后一小时原味250g | J6: 12 | K6: 93.8 | L6: 10.9 | M6: 7.8166667 | N6: 是 | W6: 10175735583817 | X6: 卡士（CLASSY.KISS）活菌奶200ml益生菌原味酸奶生牛乳风味发酵乳孕妇儿童学生早餐奶 【8瓶】餐后一小时0蔗糖250g | Y6: 卡士（CLASSY.KISS）活菌奶200ml益生菌原味酸奶生牛乳风味发酵乳孕妇儿童学生早餐奶 【8瓶】餐后一小时0蔗糖250g | Z6: 10175735583817 | AA6: 130.8 | AB6: -37
A7: 46054 | B7: 46077 | C7: 广州大区 | D7: 广州喜万佳便利店有限公司 | E7: 京东 | G7: 柏赞食品甄选店 | H7: http://item.jd.com/10209012482164.html | I7: 卡士餐后一小时原味250g | J7: 8 | K7: 78.8 | L7: 10.9 | M7: 9.85 | N7: 是 | W7: 10209012482164 | X7: 卡士（CLASSY.KISS）0蔗糖餐后一小时发酵乳250g原味酸奶益生菌酸牛奶孕妇白领早餐奶 【8瓶】AD钙牛油果味210g | Y7: 卡士（CLASSY.KISS）0蔗糖餐后一小时发酵乳250g原味酸奶益生菌酸牛奶孕妇白领早餐奶 【8瓶】AD钙牛油果味210g | Z7: 10209012482164 | AA7: 87.2 | AB7: -8.4
A8: 46054 | B8: 46077 | C8: 广州大区 | D8: 未知经销商 | E8: 淘宝/天猫 | F8: 广东东莞 | G8: 牛奶饮品批发商行 | H8: https://item.taobao.com/item.htm?id=977418776358 | I8: 卡士餐后一小时原味250g | J8: 8 | K8: 77 | L8: 10.9 | M8: 9.625 | N8: 是 | T8: 46080 | U8: 已调整 | V8: 店铺新客减11元 | W8: 977418776358 | X8: 卡士酸奶餐后一小时原味/0蔗糖风味发酵乳250g *8瓶低温酸奶整箱 | Y8: 8瓶】餐后原味 | Z8: 6096058190227 | AA8: 87.2 | AB8: -10.2
A9: 46054 | B9: 46077 | C9: 广州大区 | D9: 未知经销商 | E9: 淘宝/天猫 | F9: 广东东莞 | G9: classykiss卡士宫荼专卖店 | H9: https://detail.tmall.com/item.htm?id=969375047856 | I9: 卡士餐后一小时原味250g | J9: 24 | K9: 260 | L9: 10.9 | M9: 10.833333 | N9: 是 | T9: 46081 | U9: 未调整 | W9: 969375047856 | X9: 卡士酸奶餐后一小时风味发酵乳益生菌酸奶整箱250g*8瓶 | Y9: 24瓶】有甜味餐后一小时 | Z9: 6084922134156 | AA9: 261.6 | AB9: -1.6
A10: 46054 | B10: 46077 | C10: 深圳大区 | D10: 广东省莞诚贸易有限公司 | E10: 淘宝/天猫 | F10: 广东 东莞 | G10: 光明酸奶品牌店 | H10: https://item.taobao.com/item.htm?id=892081816033 | I10: 卡士餐后一小时原味250g | J10: 24 | K10: 260 | L10: 10.9 | M10: 10.833333 | N10: 是 | W10: 892081816033 | X10: 卡士酸奶餐后一小时风味发酵乳低温酸奶早餐奶250g/瓶 | Y10: 24瓶】餐后一小时原味 | Z10: 5906142599072 | AA10: 261.6 | AB10: -1.6
A11: 46054 | B11: 46077 | C11: 广州大区 | D11: 未知经销商 | E11: 淘宝/天猫 | F11: 广东广州 | G11: 依然食品企业店 | H11: https://item.taobao.com/item.htm?id=761549088087 | I11: 卡士餐后一小时原味250g | J11: 8 | K11: 76.5 | L11: 10.9 | M11: 9.5625 | N11: 是 | T11: 46079 | U11: 已调整 | V11: 官方立减12%省11.3元；店铺券满20减6；满2件9.5折 | W11: 761549088087 | X11: 卡士酸奶餐后一小时250g双歧杆菌风味发酵乳益生菌原味全脂早餐奶 | Y11: 【8瓶】餐后一小时原味250g | Z11: 5796901468137 | AA11: 87.2 | AB11: -10.7
A12: 46054 | B12: 46077 | C12: 广州大区 | D12: 未知经销商 | E12: 淘宝/天猫 | F12: 广东东莞 | G12: classykiss卡士宫荼专卖店 | H12: https://detail.tmall.com/item.htm?id=892370854388 | I12: 卡士餐后一小时原味250g | J12: 8 | K12: 84 | L12: 10.9 | M12: 10.5 | N12: 是 | T12: 46080 | U12: 已调整 | V12: 店铺新客减4元 | W12: 892370854388 | X12: 卡士酸奶餐后一小时风味发酵乳益生菌酸奶整箱250g*8瓶 | Y12: 8瓶】有甜味餐后一小时 | Z12: 5907167610155 | AA12: 87.2 | AB12: -3.2
A13: 46054 | B13: 46077 | C13: 广州大区 | D13: 广州喜万佳便利店有限公司 | E13: 淘宝/天猫 | F13: 广东广州 | G13: 喜萬佳超市 | H13: https://item.taobao.com/item.htm?id=542493877185 | I13: 卡士餐后一小时原味250g | J13: 8 | K13: 76.5 | L13: 10.9 | M13: 9.5625 | N13: 是 | V13: 官方立减12%省11.3元；店铺券满20减6；满2件9.5折 | W13: 542493877185 | X13: 卡士酸奶餐后一小时250g双歧杆菌风味发酵乳益生菌原味全脂早餐奶 | Y13: 【8瓶】餐后一小时0蔗糖250g | Z13: 5405702901421 | AA13: 87.2 | AB13: -10.7
A14: 46054 | B14: 46077 | C14: 上海大区 | D14: 未知经销商 | E14: 淘宝/天猫 | F14: 上海 | G14: 锦彬膳旗舰店 | H14: https://detail.tmall.com/item.htm?id=949683133616 | I14: 卡士餐后一小时原味250g | J14: 6 | K14: 65.1 | L14: 10.9 | M14: 10.85 | N14: 是 | T14: 46081 | U14: 未调整 | V14: 官方立减12%省5元 | W14: 949683133616 | X14: 卡士酸奶餐后一小时无蔗糖含膳食纤维风味发酵乳低温酸奶250g瓶装 | Y14: （蓝）卡士餐后一小时无蔗糖250g 6瓶 | Z14: 5861151928617 | AA14: 65.4 | AB14: -0.3
A15: 46054 | B15: 46077 | C15: 广州大区 | D15: 广州喜万佳便利店有限公司 | E15: 淘宝/天猫 | F15: 广东广州 | G15: 喜萬佳超市 | H15: https://item.taobao.com/item.htm?id=761463254400 | I15: 卡士餐后一小时原味250g | J15: 3 | K15: 31.6 | L15: 10.9 | M15: 10.533333 | N15: 是 | V15: 官方立减12%省13元；店铺券满20减6；满2件9.5折 | W15: 761463254400 | X15: 卡士酸奶餐后一小时无蔗糖250g双歧杆菌发酵乳0蔗糖益生菌早餐奶 | Y15: 【3瓶】餐后一小时0蔗糖250g | Z15: 5278092637083 | AA15: 32.7 | AB15: -1.1
A16: 46054 | B16: 46077 | C16: 上海大区 | D16: 未知经销商 | E16: 淘宝/天猫 | F16: 上海 | G16: 安新点健康生活馆 | H16: https://item.taobao.com/item.htm?id=610172317455 | I16: 卡士餐后一小时原味250g | J16: 24 | K16: 252 | L16: 10.9 | M16: 10.5 | N16: 是 | T16: 46081 | U16: 未调整 | V16: 淘金币频道抵扣11%起 | W16: 610172317455 | X16: 卡士酸牛奶餐后一小时250ml双歧杆菌风味发酵乳250g低温酸奶 | Y16: 餐后一小时250g,24瓶 | Z16: 4388617680285 | AA16: 261.6 | AB16: -9.6
A17: 46054 | B17: 46077 | C17: 上海大区 | D17: 昆山友吖电子商务有限公司 | E17: 淘宝/天猫 | F17: 江苏 苏州 | G17: 友吖食客 | H17: https://item.taobao.com/item.htm?id=1000040865118 | I17: 卡士餐后一小时原味250g | J17: 8 | K17: 86 | L17: 10.9 | M17: 10.75 | N17: 是 | V17: 满30.0减4.0；官方8.8折；商品券 | 满30减4 | W17: 1000040865118 | X17: 顺丰包邮卡士餐后一小时酸奶250g益生菌0蔗糖健身学生孕妇原味 | Y17: 【原味】餐后一小时250g *8瓶 | Z17: 5984492224092 | AA17: 87.2 | AB17: -1.2
A18: 46054 | B18: 46077 | C18: 上海大区 | D18: 昆山友吖电子商务有限公司 | E18: 淘宝/天猫 | F18: 江苏 苏州 | G18: 友吖食客 | H18: https://item.taobao.com/item.htm?id=910180284324 | I18: 卡士餐后一小时原味250g | J18: 12 | K18: 128 | L18: 10.9 | M18: 10.666667 | N18: 是 | V18: 满30.0减4.0；官方8.8折；淘金币频道抵扣1%起；商品券 | 满30减4 | W18: 910180284324 | X18: 卡士餐后一小时酸奶双歧杆菌风味原味零糖益生菌发酵乳早餐奶250g | Y18: 餐后一小时原味250g,12瓶 | Z18: 5772297761075 | AA18: 130.8 | AB18: -2.8
A19: 46054 | B19: 46077 | C19: 上海大区 | D19: 上海旭禄商贸有限公司 | E19: 淘宝/天猫 | F19: 上海 | G19: 小强の酒水饮料铺 | H19: https://item.taobao.com/item.htm?id=873035397825 | I19: 卡士餐后一小时原味250g | J19: 6 | K19: 59.4 | L19: 10.9 | M19: 9.9 | N19: 是 | V19: 淘金币频道抵扣10%起 | W19: 873035397825 | X19: 卡士餐后一小时酸奶250g*12瓶益生菌低温风味发酵乳 | Y19: 餐后一小时250g*6瓶【保质期25天】 | Z19: 5706029088695 | AA19: 65.4 | AB19: -6
A20: 46054 | B20: 46077 | C20: 上海大区 | D20: 昆山友吖电子商务有限公司 | E20: 淘宝/天猫 | F20: 江苏 苏州 | G20: 友吖食品专营店 | H20: https://item.taobao.com/item.htm?id=998548255197 | I20: 卡士餐后一小时原味250g | J20: 8 | K20: 86 | L20: 10.9 | M20: 10.75 | N20: 是 | V20: 满30.0减4.0；限时补贴0.1元；官方立减9.5元；淘金币频道抵扣5%起；商品券 | 满30减4 | W20: 998548255197 | X20: 顺丰！卡士餐后一小时0蔗糖250g原味双歧杆菌孕妇老人风味发酵乳 | Y20: 【原味】餐后一小时250g*8瓶 | Z20: 5984291388980 | AA20: 87.2 | AB20: -1.2
A21: 46054 | B21: 46077 | C21: 华东大区 | D21: 未知经销商 | E21: 淘宝/天猫 | F21: 江苏 苏州 | G21: 天润乳业苏州企业店 | H21: https://item.taobao.com/item.htm?id=895120131196 | I21: 卡士餐后一小时原味250g | J21: 12 | K21: 128 | L21: 10.9 | M21: 10.666667 | N21: 是 | T21: 46079 | U21: 已调整 | V21: 满30.0减4.0；官方8.8折；淘金币频道抵扣3%起；商品券 | 满30减4 | W21: 895120131196 | X21: 卡士餐后一小时酸奶双歧杆菌风味原味零糖益生菌发酵乳早餐奶250g | Y21: 餐后一小时原味250g,12瓶 | Z21: 5914957147772 | AA21: 130.8 | AB21: -2.8
A22: 46054 | B22: 46077 | C22: 深圳大区 | D22: 未知经销商 | E22: 淘宝/天猫 | F22: 广东 深圳 | G22: 官方国货甄选 | H22: https://item.taobao.com/item.htm?id=1001126801431 | I22: 卡士餐后一小时原味250g | J22: 6 | K22: 64.7 | L22: 10.9 | M22: 10.783333 | N22: 是 | T22: 46081 | U22: 未调整 | V22: 补贴7.2元 | W22: 1001126801431 | X22: 餐后一小时发酵乳250g双歧杆菌原味酸奶孕妇老人儿童早餐奶蔗糖 | Y22: 原味,6瓶 | Z22: 6152764086791 | AA22: 65.4 | AB22: -0.7
A23: 46054 | B23: 46077 | C23: 上海大区 | D23: 上海旭禄商贸有限公司 | E23: 淘宝/天猫 | F23: 上海 | G23: 小强の酒水饮料铺 | H23: https://item.taobao.com/item.htm?id=858347041534 | I23: 卡士餐后一小时原味250g | J23: 9 | K23: 98 | L23: 10.9 | M23: 10.888889 | N23: 是 | V23: 淘金币频道抵扣10%起；最高10元，部分用户可领，限秒杀频道领用；最高5元，部分用户可领，限秒杀频道领用 | W23: 858347041534 | X23: 卡士零糖酸奶原味250g*3瓶餐后一小时益生菌低温学生奶 | Y23: 餐后一小时250g*9瓶【保质期25天】 | Z23: 5849803619038 | AA23: 98.1 | AB23: -0.1
A24: 46054 | B24: 46077 | C24: 上海大区 | D24: 昆山友吖电子商务有限公司 | E24: 淘宝/天猫 | F24: 江苏 苏州 | G24: 友吖食品专营店 | H24: https://item.taobao.com/item.htm?id=900215278913 | I24: 卡士餐后一小时原味250g | J24: 12 | K24: 124.35 | L24: 10.9 | M24: 10.3625 | N24: 是 | V24: 直降16.21元；淘金币频道抵扣1%起；最高10元，部分用户可领，限秒杀频道领用；最高5元，部分用户可领，限秒杀频道领用 | W24: 900215278913 | X24: 顺丰包邮卡士酸奶餐后一小时250g*12瓶整箱风味发酵乳零0蔗糖早餐 | Y24: 【组合】原味+零蔗糖250g*12瓶 | Z24: 5755597644772 | AA24: 130.8 | AB24: -6.45
A25: 46054 | B25: 46077 | C25: 广州大区 | D25: 未知经销商 | E25: 淘宝/天猫 | F25: 广东广州 | G25: 依然食品企业店 | H25: https://item.taobao.com/item.htm?id=542495133129 | I25: 卡士餐后一小时原味250g | J25: 8 | K25: 83.8 | L25: 10.9 | M25: 10.475 | N25: 是 | T25: 46079 | U25: 已调整 | W25: 542495133129 | X25: 卡士酸奶餐后一小时250g双歧杆菌风味发酵乳益生菌低温原味早餐奶 | Y25: 口味:【礼盒装】8瓶餐后一小时原味250g | Z25: 5643677927571 | AA25: 87.2 | AB25: -3.4
A26: 46054 | B26: 46077 | C26: 广州大区 | D26: 未知经销商 | E26: 淘宝/天猫 | F26: 广东 广州 | G26: 依然食品企业店 | H26: https://item.taobao.com/item.htm?id=761678711206 | I26: 卡士餐后一小时原味250g | J26: 8 | K26: 83.8 | L26: 10.9 | M26: 10.475 | N26: 是 | T26: 46079 | U26: 已调整 | W26: 761678711206 | X26: 卡士酸奶餐后一小时无蔗糖250g双歧杆菌发酵乳益生菌原味早餐奶 | Y26: 口味:【礼盒装】8瓶餐后一小时0蔗糖250g | Z26: 5644809638476 | AA26: 87.2 | AB26: -3.4
A27: 46054 | B27: 46077 | C27: 上海大区 | D27: 昆山友吖电子商务有限公司 | E27: 淘宝/天猫 | F27: 江苏苏州 | G27: 友吖食品专营店 | H27: http://item.taobao.com/item.htm?id=900215278913 | I27: 卡士餐后一小时原味250g | J27: 6 | K27: 62.79 | L27: 10.9 | M27: 10.465 | N27: 是
A28: 46054 | B28: 46078 | C28: 深圳大区 | D28: 未知经销商 | E28: 淘宝/天猫 | F28: 广东深圳 | G28: 国货严选旗舰 | H28: https://e.tb.cn/h.7HKNOuoGyHQbKzk?tk=RerPU8SwU2g | I28: 卡士餐后一小时无蔗糖原味250g | J28: 9 | K28: 96.28 | L28: 10.9 | M28: 10.697778 | N28: 是 | T28: 46079 | U28: 已调整 | AA28: 98.1 | AB28: -1.82
A29: 46054 | B29: 46078 | C29: 上海大区 | D29: 未知经销商 | E29: 淘宝/天猫 | F29: 上海 | G29: 锦彬膳旗舰店 | H29: http://item.taobao.com/item.htm?id=949683133616 | I29: 卡士餐后一小时无蔗糖原味250g | J29: 10 | K29: 105.2 | L29: 10.9 | M29: 10.52 | N29: 是 | T29: 46081 | U29: 未调整 | AA29: 109 | AB29: -3.8
A30: 46054 | B30: 46078 | C30: 广州大区 | D30: 未知经销商 | E30: 淘宝/天猫 | F30: 广东东莞 | G30: 牛奶饮品批发商行 | H30: https://e.tb.cn/h.7w1EnQ2PXpJ9TBm?tk=hvJoUlrXMD7 | I30: 卡士餐后一小时原味250g | J30: 1 | K30: 9.62 | L30: 10.9 | M30: 9.62 | N30: 是 | T30: 46080 | U30: 已下架 | AA30: 10.9 | AB30: -1.28
A31: 46054 | B31: 46078 | C31: 华东大区 | D31: 未知经销商 | E31: 淘宝/天猫 | F31: 浙江嘉兴 | G31: 江南本美 | H31: https://e.tb.cn/h.7vcn4WgW0BLUSUl?tk=si4IUlrUQTZ | I31: 卡士餐后一小时原味250g | J31: 1 | K31: 9.78 | L31: 10.9 | M31: 9.78 | N31: 是 | T31: 46079 | U31: 已调整 | AA31: 10.9 | AB31: -1.12
A32: 46054 | B32: 46078 | C32: 华北大区 | D32: 未知经销商 | E32: 淘宝/天猫 | F32: 北京 | G32: 北京万腾牛奶超市 | H32: https://e.tb.cn/h.7EYLSGTypJvTanp?tk=imhRUlr6uKN | I32: 卡士餐后一小时原味250g | J32: 1 | K32: 9.56 | L32: 10.9 | M32: 9.56 | N32: 是 | T32: 46079 | U32: 已调整 | AA32: 10.9 | AB32: -1.34
A33: 46054 | B33: 46078 | C33: 广州大区 | D33: 广州喜万佳便利店有限公司 | E33: 京东 | G33: 喜万佳甄选店 | H33: https://item.jd.com/10177362415232.html | I33: 卡士餐后一小时无蔗糖原味250g | J33: 8 | K33: 82.8 | L33: 10.9 | M33: 10.35 | N33: 是 | W33: 10177362415232 | X33: 卡士酸奶手握瓶活菌奶220g低温益生菌原味酸奶孕妇儿童学生早餐奶【8瓶】餐后一小时250g | Y33: 【8瓶】餐后一小时250g | Z33: 10177362415232 | AA33: 87.2 | AB33: -4.4
A34: 46054 | B34: 46078 | C34: 广州大区 | D34: 广州喜万佳便利店有限公司 | E34: 京东 | G34: 喜万佳甄选店 | H34: https://item.jd.com/10206164441741.html | I34: 卡士餐后一小时无蔗糖原味250g | J34: 8 | K34: 79.8 | L34: 10.9 | M34: 9.975 | N34: 是 | W34: 10206164441741 | X34: 卡士007酸奶原味100g三连杯益生菌风味发酵乳低温生牛乳全脂早餐奶【8瓶】餐后一小时0蔗糖250g | Y34: 【8瓶】餐后一小时0蔗糖250g | Z34: 10206164441741 | AA34: 87.2 | AB34: -7.4
A35: 46054 | B35: 46078 | C35: 广州大区 | D35: 广州喜万佳便利店有限公司 | E35: 京东 | G35: 柏赞食品甄选店 | H35: https://item.jd.com/10175773352591.html | I35: 卡士餐后一小时原味250g | J35: 10 | K35: 87.8 | L35: 10.9 | M35: 8.78 | N35: 是 | W35: 10175773352591 | X35: 卡士（CLASSY.KISS）活菌奶720ml低温原味酸奶益生菌生牛乳风味发酵乳孕妇学生酸牛奶【8瓶】餐后一小时0蔗糖250g | Y35: 【8瓶】餐后一小时0蔗糖250g | Z35: 10175773352591 | AA35: 109 | AB35: -21.2
A36: 46054 | B36: 46078 | C36: 广州大区 | D36: 广州喜万佳便利店有限公司 | E36: 京东 | G36: 柏赞食品甄选店 | H36: https://item.jd.com/10175735583817.html | I36: 卡士餐后一小时原味250g | J36: 12 | K36: 87.8 | L36: 10.9 | M36: 7.3166667 | N36: 是 | W36: 10175735583817 | X36: 卡士（CLASSY.KISS）活菌奶200ml益生菌原味酸奶生牛乳风味发酵乳孕妇儿童学生早餐奶【8瓶】餐后一小时0蔗糖250g | Y36: 【8瓶】餐后一小时0蔗糖250g | Z36: 10175735583817 | AA36: 130.8 | AB36: -43
A37: 46054 | B37: 46078 | C37: 广州大区 | D37: 广州喜万佳便利店有限公司 | E37: 京东 | G37: 柏赞食品甄选店 | H37: https://item.jd.com/10209012482164.html | I37: 卡士餐后一小时原味250g | J37: 8 | K37: 72.8 | L37: 10.9 | M37: 9.1 | N37: 是 | W37: 10209012482164 | X37: 卡士（CLASSY.KISS）0蔗糖餐后一小时发酵乳250g原味酸奶益生菌酸牛奶孕妇白领早餐奶【8瓶】AD钙牛油果味210g | Y37: 【8瓶】AD钙牛油果味210g | Z37: 10209012482164 | AA37: 87.2 | AB37: -14.4
A38: 46054 | B38: 46078 | C38: 无法判定大区 | D38: 未知经销商 | E38: 京东 | G38: 沃途食品店 | H38: https://item.jd.com/10161032513827.html | I38: 卡士餐后一小时原味250g | J38: 8 | K38: 61.8 | L38: 10.9 | M38: 7.725 | N38: 是 | T38: 46079 | U38: 已调整 | W38: 10161032513827 | X38: 卡士（CLASSY.KISS）酸奶餐后一小时发酵乳250g*12瓶原味营养双歧杆菌风味发酵乳 餐后一小时原味 3瓶 | Y38: 卡士（CLASSY.KISS）酸奶餐后一小时发酵乳250g*12瓶原味营养双歧杆菌风味发酵乳 餐后一小时原味 3瓶 | Z38: 10161032513827 | AA38: 87.2 | AB38: -25.4
A39: 46054 | B39: 46078 | C39: 无法判定大区 | D39: 未知经销商 | E39: 京东 | G39: 玲柔好物店 | H39: https://item.jd.com/10177000430970.html | I39: 卡士餐后一小时原味250g | J39: 3 | K39: 25.7 | L39: 10.9 | M39: 8.5666667 | N39: 是 | T39: 46079 | U39: 已调整 | W39: 10177000430970 | X39: 卡士（CLASSY.KISS）CLASSYKISS 卡士零糖酸奶原味250g3瓶餐后一小时益生菌低温学生奶 0糖餐后一小时250g*1瓶保质 | Y39: 卡士（CLASSY.KISS）CLASSYKISS 卡士零糖酸奶原味250g3瓶餐后一小时益生菌低温学生奶 0糖餐后一小时250g*1瓶保质 | Z39: 10177000430970 | AA39: 32.7 | AB39: -7
A40: 46054 | B40: 46078 | C40: 无法判定大区 | D40: 未知经销商 | E40: 京东 | G40: MM 會员店 | H40: https://item.jd.com/10148054852544.html | I40: 卡士餐后一小时原味250g | J40: 10 | K40: 105.77 | L40: 10.9 | M40: 10.577 | N40: 是 | T40: 46079 | U40: 已调整 | W40: 10148054852544 | X40: 卡士酸奶餐后一小时无蔗糖含纤维风味发酵乳低温酸奶250g瓶装 卡士酸奶无蔗糖250g瓶装*10 | Y40: 卡士酸奶餐后一小时无蔗糖含纤维风味发酵乳低温酸奶250g瓶装 卡士酸奶无蔗糖250g瓶装*10 | Z40: 10148054852544 | AA40: 109 | AB40: -3.23
...

Sheet 违规未知经销商
